Workbook

Sheet README
A1: Concurrences Gate 2 Expert Review Template
A3: Purpose | B3: This workbook is for reviewing generated answers and retrieved sources for Approved benchmark questions only.
A5: How experts should use this file
A6: 1. Open the tab for your question, for example Q01.
A7: 2. Review the generated answer and the sources retrieved by the system.
A8: 3. For each legal claim, mark whether the cited source supports it.
A9: 4. Add a short comment only where something must be fixed or clarified.
A10: 5. Mark the final expert verdict at the bottom of each question tab.
A11: 6. The team will use Review Status and Scoring Summary to track progress and calculate metrics.
A14: Key dates
A15: Answers and retrieval sets generated by | B15: 46251
A16: Expert claim-by-claim review completed by | B16: 2026-08-21
A18: Batch 1
A19: Q15
A20: Q16
A21: Q17
A22: Q25
A23: Q28 ⚠️
A24: Q29
A25: Q35
A26: Q41

Sheet Review Status
A1: Review Status
A3: Question ID | B3: Topic | C3: Scope | D3: Question | E3: Expert review status | F3: Reviewer | G3: Main issue / follow-up | H3: Open tab
A4: 1 | B4: Food delivery — market definition | C4: EU + UK + ES | D4: The relevant market in a food-delivery acquisition — how have the Commission and national authorities defined the relevant product and geographic markets, and on what rationales? | E4: ='Q01'!B40 | F4: ='Q01'!B37 | G4: ='Q01'!B39 | H4: =HYPERLINK("https://docs.google.com/spreadsheets/d/1SGTTCNk9crU1EZRgL9dlNhuv_RvcJLmSnfJtXz3RjEE/edit#gid=522724517&range=A1","Open")
A5: 2 | B5: Food delivery — multi-sided platforms | C5: EU + UK + ES | D5: Food delivery as a multi-sided platform — have authorities analysed these platforms as two- or multi-sided markets, and which sides actually entered the analysis? | E5: ='Q02'!B40 | F5: ='Q02'!B37 | G5: ='Q02'!B39 | H5: =HYPERLINK("https://docs.google.com/spreadsheets/d/1SGTTCNk9crU1EZRgL9dlNhuv_RvcJLmSnfJtXz3RjEE/edit#gid=297064813&range=A1","Open")
A6: 3 | B6: Food delivery — market boundary | C6: UK (ES colour) | D6: Grocery, quick commerce, and the market boundary — separate markets from restaurant meal delivery, or one broad on-demand delivery market? | E6: ='Q03'!B40 | F6: ='Q03'!B37 | G6: ='Q03'!B39 | H6: =HYPERLINK("https://docs.google.com/spreadsheets/d/1SGTTCNk9crU1EZRgL9dlNhuv_RvcJLmSnfJtXz3RjEE/edit#gid=1817894368&range=A1","Open")
A7: 4 | B7: Food delivery — failing-firm defence | C7: UK | D7: The failing-firm defence in food delivery — has an exiting-firm counterfactual ever been accepted, did it survive to the final decision, and on what evidence? | E7: ='Q04'!B40 | F7: ='Q04'!B37 | G7: ='Q04'!B39 | H7: =HYPERLINK("https://docs.google.com/spreadsheets/d/1SGTTCNk9crU1EZRgL9dlNhuv_RvcJLmSnfJtXz3RjEE/edit#gid=1366002813&range=A1","Open")
A8: 5 | B8: Food delivery — COVID-19 | C8: UK | D8: COVID-19 in the competitive assessment — how did the pandemic actually enter the analysis: counterfactual, market definition, or not at all? | E8: ='Q05'!B40 | F8: ='Q05'!B37 | G8: ='Q05'!B39 | H8: =HYPERLINK("https://docs.google.com/spreadsheets/d/1SGTTCNk9crU1EZRgL9dlNhuv_RvcJLmSnfJtXz3RjEE/edit#gid=1044237719&range=A1","Open")
A9: 6 | B9: Food delivery — potential competition | C9: UK | D9: Potential competition and re-entry — where the acquirer is not active in the UK, how has the CMA treated entry or re-entry absent the merger? | E9: ='Q06'!B40 | F9: ='Q06'!B37 | G9: ='Q06'!B39 | H9: =HYPERLINK("https://docs.google.com/spreadsheets/d/1SGTTCNk9crU1EZRgL9dlNhuv_RvcJLmSnfJtXz3RjEE/edit#gid=1384317690&range=A1","Open")
A10: 7 | B10: Food delivery — no-poach agreements | C10: EU | D10: No-poach agreements under Article 101 — can a reciprocal agreement not to hire each other's staff infringe Article 101, and what is the leading precedent and fine? | E10: ='Q07'!B40 | F10: ='Q07'!B37 | G10: ='Q07'!B39 | H10: =HYPERLINK("https://docs.google.com/spreadsheets/d/1SGTTCNk9crU1EZRgL9dlNhuv_RvcJLmSnfJtXz3RjEE/edit#gid=480477156&range=A1","Open")
A11: 8 | B11: Food delivery — remedies | C11: EU + UK + ES | D11: Remedies in food-delivery mergers — which European reviews ended in remedies or commitments, and what did they look like? | E11: ='Q08'!B40 | F11: ='Q08'!B37 | G11: ='Q08'!B39 | H11: =HYPERLINK("https://docs.google.com/spreadsheets/d/1SGTTCNk9crU1EZRgL9dlNhuv_RvcJLmSnfJtXz3RjEE/edit#gid=255925358&range=A1","Open")
A12: 9 | B12: Food delivery — Spanish practice | C12: ES | D12: The Spanish (CNMC) food-delivery reviews — what is the CNMC's decisional practice, how many cases, and how were they resolved? | E12: ='Q09'!B40 | F12: ='Q09'!B37 | G12: ='Q09'!B39 | H12: =HYPERLINK("https://docs.google.com/spreadsheets/d/1SGTTCNk9crU1EZRgL9dlNhuv_RvcJLmSnfJtXz3RjEE/edit#gid=2000953996&range=A1","Open")
A13: 10 | B13: Food delivery — minority shareholdings | C13: EU + UK | D13: Material influence and minority shareholdings — on what basis did the CMA take jurisdiction over a c.16% stake, and how else have authorities treated minority shareholdings in merger control? | E13: ='Q10'!B40 | F13: ='Q10'!B37 | G13: ='Q10'!B39 | H13: =HYPERLINK("https://docs.google.com/spreadsheets/d/1SGTTCNk9crU1EZRgL9dlNhuv_RvcJLmSnfJtXz3RjEE/edit#gid=1185272458&range=A1","Open")
A14: 11 | B14: Food delivery — evolution of practice | C14: EU + UK + ES | D14: The evolution of European food-delivery merger control, 2017–2025 — how has practice evolved from the first national marketplace consolidations to the recent Commission decisions? | E14: ='Q11'!B40 | F14: ='Q11'!B37 | G14: ='Q11'!B39 | H14: =HYPERLINK("https://docs.google.com/spreadsheets/d/1SGTTCNk9crU1EZRgL9dlNhuv_RvcJLmSnfJtXz3RjEE/edit#gid=1792039940&range=A1","Open")
A15: 12 | B15: Dawn raids — legal professional privilege | C15: France | D15: At what stage is attorney-client privilege breached during a dawn raid — when the inspector reads the document, or only when it is later used? | E15: ='Q12'!B40 | F15: ='Q12'!B37 | G15: ='Q12'!B39 | H15: =HYPERLINK("https://docs.google.com/spreadsheets/d/1SGTTCNk9crU1EZRgL9dlNhuv_RvcJLmSnfJtXz3RjEE/edit#gid=1162681808&range=A1","Open")
A16: 13 | B16: Dawn raids — personal data | C16: France | D16: Under what conditions must the Competition Authority protect personal data during a dawn raid? Does the GDPR apply? Must documents be sealed on request? | E16: ='Q13'!B40 | F16: ='Q13'!B37 | G16: ='Q13'!B39 | H16: =HYPERLINK("https://docs.google.com/spreadsheets/d/1SGTTCNk9crU1EZRgL9dlNhuv_RvcJLmSnfJtXz3RjEE/edit#gid=1447177020&range=A1","Open")
A17: 14 | B17: Dawn raids — challenging a seizure | C17: France | D17: After a dawn raid, can the President of the Court of Appeal be seized in interim proceedings to urgently resolve attorney-client privilege disputes? On what legal basis and under what conditions? | E17: ='Q14'!B40 | F17: ='Q14'!B37 | G17: ='Q14'!B39 | H17: =HYPERLINK("https://docs.google.com/spreadsheets/d/1SGTTCNk9crU1EZRgL9dlNhuv_RvcJLmSnfJtXz3RjEE/edit#gid=1075356362&range=A1","Open")
A18: 15 | B18: Dawn raids — legal professional privilege | C18: EU | D18: At what stage is attorney-client privilege breached during a European Commission inspection under Article 20 of Regulation 1/2003 — when the inspector reads the document, or only when the Commission later uses it? | E18: ='Q15'!B40 | F18: ='Q15'!B37 | G18: ='Q15'!B39 | H18: =HYPERLINK("https://docs.google.com/spreadsheets/d/1SGTTCNk9crU1EZRgL9dlNhuv_RvcJLmSnfJtXz3RjEE/edit#gid=620738959&range=A1","Open")
A19: 16 | B19: Dawn raids — personal data | C19: EU | D19: Under what conditions must the European Commission protect personal data during an inspection? Does the GDPR apply? Must documents be sealed on request? | E19: ='Q16'!B40 | F19: ='Q16'!B37 | G19: ='Q16'!B39 | H19: =HYPERLINK("https://docs.google.com/spreadsheets/d/1SGTTCNk9crU1EZRgL9dlNhuv_RvcJLmSnfJtXz3RjEE/edit#gid=141567022&range=A1","Open")
A20: 17 | B20: Dawn raids — challenging a seizure | C20: EU | D20: What procedural avenues exist to challenge seizure of privileged documents after a European Commission inspection? | E20: ='Q17'!B40 | F20: ='Q17'!B37 | G20: ='Q17'!B39 | H20: =HYPERLINK("https://docs.google.com/spreadsheets/d/1SGTTCNk9crU1EZRgL9dlNhuv_RvcJLmSnfJtXz3RjEE/edit#gid=393784023&range=A1","Open")
A21: 18 | B21: Dawn raids — legal professional privilege | C21: US | D21: At what stage is attorney-client privilege breached when US antitrust authorities gather documents — when the investigator reads the document, or only when it is later used? | E21: ='Q18'!B40 | F21: ='Q18'!B37 | G21: ='Q18'!B39 | H21: =HYPERLINK("https://docs.google.com/spreadsheets/d/1SGTTCNk9crU1EZRgL9dlNhuv_RvcJLmSnfJtXz3RjEE/edit#gid=631067114&range=A1","Open")
A22: 19 | B22: Dawn raids — personal data | C22: US | D22: What protections apply to personal or otherwise sensitive data gathered by U.S. antitrust authorities, and on what grounds may material that is irrelevant, overbroad, privileged, or otherwise protected be segregated, withheld, returned, or destroyed? | E22: ='Q19'!B40 | F22: ='Q19'!B37 | G22: ='Q19'!B39 | H22: =HYPERLINK("https://docs.google.com/spreadsheets/d/1SGTTCNk9crU1EZRgL9dlNhuv_RvcJLmSnfJtXz3RjEE/edit#gid=1900000019&range=A1","Open")
A23: 20 | B23: Dawn raids — challenging a seizure | C23: US | D23: What procedural avenues exist to challenge the seizure, review, retention, or use of privileged documents following the execution of a search warrant in a criminal antitrust investigation, and how do those remedies differ from procedures for modifying or setting aside a subpoena or Civil Investigative Demand (CID) in a civil antitrust investigation? | E23: ='Q20'!B40 | F23: ='Q20'!B37 | G23: ='Q20'!B39 | H23: =HYPERLINK("https://docs.google.com/spreadsheets/d/1SGTTCNk9crU1EZRgL9dlNhuv_RvcJLmSnfJtXz3RjEE/edit#gid=1900000020&range=A1","Open")
A24: 21 | B24: Food delivery — data access | C24: EU + UK | D24: Where a platform like Uber leverages data collected across its ecosystem to improve and strengthen its food delivery arm, how would such conduct be characterised under EU competition law — as tying/bundling, as an exploitative abuse, as leveraging into an adjacent market, or as a distinct data-driven theory of harm? Which category best fits, and what would be required to establish it under Article 102 TFEU? | E24: ='Q21'!B40 | F24: ='Q21'!B37 | G24: ='Q21'!B39 | H24: =HYPERLINK("https://docs.google.com/spreadsheets/d/1SGTTCNk9crU1EZRgL9dlNhuv_RvcJLmSnfJtXz3RjEE/edit#gid=832901646&range=A1","Open")
A25: 22 | B25: Food delivery — own fleet vs marketplace | C25: EU + UK + ES | D25: Can a food-delivery platform qualify as a provider of online intermediation services within the meaning of the P2B Regulation (EU) 2019/1150 — and if so, which obligations would it additionally have to comply with should it be designated as a gatekeeper under the DMA? | E25: ='Q22'!B40 | F25: ='Q22'!B37 | G25: ='Q22'!B39 | H25: =HYPERLINK("https://docs.google.com/spreadsheets/d/1SGTTCNk9crU1EZRgL9dlNhuv_RvcJLmSnfJtXz3RjEE/edit#gid=1144467272&range=A1","Open")
A26: 23 | B26: Food delivery — which authority reviews | C26: EU + UK + ES | D26: Food-delivery transactions frequently fall below the EU Merger Regulation turnover thresholds yet raise cross-border concerns. In light of the CJEU's Illumina/Grail judgment restricting Article 22 upward referrals for deals that do not meet any national threshold, what mechanisms remain for the Commission to capture a below-threshold food-delivery 'killer acquisition'? | E26: ='Q23'!B40 | F26: ='Q23'!B37 | G26: ='Q23'!B39 | H26: =HYPERLINK("https://docs.google.com/spreadsheets/d/1SGTTCNk9crU1EZRgL9dlNhuv_RvcJLmSnfJtXz3RjEE/edit#gid=1842731106&range=A1","Open")
A27: 24 | B27: Dawn raids — legal professional privilege | C27: EU | D27: Does legal professional privilege in EU competition law cover advice from a company's own in-house lawyers? How have the courts justified where the line falls, and what does that mean in practice during an inspection? | E27: ='Q24'!B40 | F27: ='Q24'!B37 | G27: ='Q24'!B39 | H27: =HYPERLINK("https://docs.google.com/spreadsheets/d/1SGTTCNk9crU1EZRgL9dlNhuv_RvcJLmSnfJtXz3RjEE/edit#gid=358280174&range=A1","Open")
A28: 25 | B28: Dawn raids — legal professional privilege | C28: France | D28: Where a French dawn raid seizes a mailbox or a set of files in bulk and privileged correspondence is found inside afterwards, what is the procedure for having it returned or destroyed, and who decides? | E28: ='Q25'!B40 | F28: ='Q25'!B37 | G28: ='Q25'!B39 | H28: =HYPERLINK("https://docs.google.com/spreadsheets/d/1SGTTCNk9crU1EZRgL9dlNhuv_RvcJLmSnfJtXz3RjEE/edit#gid=1832451430&range=A1","Open")
A29: 26 | B29: Dawn raids — challenging a seizure | C29: France | D29: French law separates a challenge to the order authorising a dawn raid from a challenge to how the raid was carried out. What are the two routes, who hears each, what are the time limits, and what can each achieve? | E29: ='Q26'!B40 | F29: ='Q26'!B37 | G29: ='Q26'!B39 | H29: =HYPERLINK("https://docs.google.com/spreadsheets/d/1SGTTCNk9crU1EZRgL9dlNhuv_RvcJLmSnfJtXz3RjEE/edit#gid=1060349846&range=A1","Open")
A30: 27 | B30: Dawn raids — the inspection decision | C30: EU | D30: What is the extent of the Commission's duty to state reasons under Article 20(4) of Regulation 1/2003 as regards the subject matter and purpose of an inspection decision and the identification of its addressees — and what are the consequences, in light of Nexans, Deutsche Bahn and Les Laboratoires Servier, where the scope of the inspection exceeds the reasonable grounds (indicia) actually in the Commission's possession? | E30: ='Q27'!B40 | F30: ='Q27'!B37 | G30: ='Q27'!B39 | H30: =HYPERLINK("https://docs.google.com/spreadsheets/d/1SGTTCNk9crU1EZRgL9dlNhuv_RvcJLmSnfJtXz3RjEE/edit#gid=854637919&range=A1","Open")
A31: 28 | B31: Dawn raids — the inspection decision | C31: EU | D31: Can an inspection decision be annulled in part where the Commission's evidence supports only some of the suspected infringement period it covers, and what then happens to material already gathered? | E31: ='Q28'!B40 | F31: ='Q28'!B37 | G31: ='Q28'!B39 | H31: =HYPERLINK("https://docs.google.com/spreadsheets/d/1SGTTCNk9crU1EZRgL9dlNhuv_RvcJLmSnfJtXz3RjEE/edit#gid=481311560&range=A1","Open")
A32: 29 | B32: Dawn raids — the inspection decision | C32: France | D32: How specific must a French dawn-raid authorisation be about the premises to be visited, the practices suspected, and the period covered? What has been held insufficient? | E32: ='Q29'!B40 | F32: ='Q29'!B37 | G32: ='Q29'!B39 | H32: =HYPERLINK("https://docs.google.com/spreadsheets/d/1SGTTCNk9crU1EZRgL9dlNhuv_RvcJLmSnfJtXz3RjEE/edit#gid=1094927511&range=A1","Open")
A33: 30 | B33: Dawn raids — obstruction and seals | C33: EU | D33: Does the obstruction regime of Article 23(1) of Regulation 1/2003 — conceived for physical records and corporate email — still fit an environment of ephemeral, encrypted messaging on employees' personal devices? Where does the deletion of a WhatsApp or Signal message during or ahead of an inspection cross from ordinary personal housekeeping into a sanctionable procedural infringement, and how must intent and attribution be established when the device and the account belong to the individual rather than the undertaking? | E33: ='Q30'!B40 | F33: ='Q30'!B37 | G33: ='Q30'!B39 | H33: =HYPERLINK("https://docs.google.com/spreadsheets/d/1SGTTCNk9crU1EZRgL9dlNhuv_RvcJLmSnfJtXz3RjEE/edit#gid=719176577&range=A1","Open")
A34: 31 | B34: Dawn raids — obstruction and seals | C34: EU | D34: To what extent may an undertaking be fined for the breaking of a seal in the absence of any fault or intent, and how is that reconciled with the presumption of innocence? | E34: ='Q31'!B40 | F34: ='Q31'!B37 | G34: ='Q31'!B39 | H34: =HYPERLINK("https://docs.google.com/spreadsheets/d/1SGTTCNk9crU1EZRgL9dlNhuv_RvcJLmSnfJtXz3RjEE/edit#gid=987315445&range=A1","Open")
A35: 32 | B35: Dawn raids — obstruction and seals | C35: France | D35: What behavior during a French dawn raid (OVS) exposes a company to obstruction liability, and what training precautions follow from recent enforcement? | E35: ='Q32'!B40 | F35: ='Q32'!B37 | G35: ='Q32'!B39 | H35: =HYPERLINK("https://docs.google.com/spreadsheets/d/1SGTTCNk9crU1EZRgL9dlNhuv_RvcJLmSnfJtXz3RjEE/edit#gid=1892631162&range=A1","Open")
A36: 33 | B36: Dawn raids — obstruction and preservation of evidence | C36: US | D36: What consequences may follow from obstructing an actual or contemplated federal antitrust investigation, including by destroying, altering, or concealing evidence, and when do separate legal obligations to preserve potentially relevant evidence arise? | E36: ='Q33'!B40 | F36: ='Q33'!B37 | G36: ='Q33'!B39 | H36: =HYPERLINK("https://docs.google.com/spreadsheets/d/1SGTTCNk9crU1EZRgL9dlNhuv_RvcJLmSnfJtXz3RjEE/edit#gid=1900000037&range=A1","Open")
A37: 34 | B37: Dawn raids — questioning staff | C37: EU | D37: To what extent may the Commission compel answers under Article 20(2)(e) of Regulation 1/2003 before the privilege against self-incrimination intervenes — and how the distinction between answering questions of fact and admitting an infringement remain workable in practice? | E37: ='Q34'!B40 | F37: ='Q34'!B37 | G37: ='Q34'!B39 | H37: =HYPERLINK("https://docs.google.com/spreadsheets/d/1SGTTCNk9crU1EZRgL9dlNhuv_RvcJLmSnfJtXz3RjEE/edit#gid=1725701280&range=A1","Open")
A38: 35 | B38: Dawn raids — questioning staff | C38: France | D38: Can employees be required to answer questions during a French dawn raid, and what protection against self-incrimination do they and the company have? | E38: ='Q35'!B40 | F38: ='Q35'!B37 | G38: ='Q35'!B39 | H38: =HYPERLINK("https://docs.google.com/spreadsheets/d/1SGTTCNk9crU1EZRgL9dlNhuv_RvcJLmSnfJtXz3RjEE/edit#gid=786847173&range=A1","Open")
A39: 36 | B39: Dawn raids — questioning staff | C39: US | D39: How does the Fifth Amendment privilege against self-incrimination apply in a U.S. antitrust investigation to compelled oral testimony versus the production of documents? Why does the privilege belong to natural persons rather than corporations, and how does the collective-entity doctrine affect an individual custodian who is required to produce corporate records? | E39: ='Q36'!B40 | F39: ='Q36'!B37 | G39: ='Q36'!B39 | H39: =HYPERLINK("https://docs.google.com/spreadsheets/d/1SGTTCNk9crU1EZRgL9dlNhuv_RvcJLmSnfJtXz3RjEE/edit#gid=1900000040&range=A1","Open")
A40: 37 | B40: Dawn raids — electronic data | C40: EU | D40: May the Commission take a forensic copy of a company's electronic data and carry on examining it at its own premises after the inspection has ended? What safeguards apply, and what rights does the company keep over that copy? | E40: ='Q37'!B40 | F40: ='Q37'!B37 | G40: ='Q37'!B39 | H40: =HYPERLINK("https://docs.google.com/spreadsheets/d/1SGTTCNk9crU1EZRgL9dlNhuv_RvcJLmSnfJtXz3RjEE/edit#gid=581550900&range=A1","Open")
A41: 38 | B41: Dawn raids — electronic data | C41: EU | D41: Whose interests prevail when an inspection captures the private communications of employees who are not themselves under investigation — the Commission's investigative reach, or the privacy protected by Articles 7 and 8 of the Charter? And when does an undertaking's effort to shield that data become obstruction? | E41: ='Q38'!B40 | F41: ='Q38'!B37 | G41: ='Q38'!B39 | H41: =HYPERLINK("https://docs.google.com/spreadsheets/d/1SGTTCNk9crU1EZRgL9dlNhuv_RvcJLmSnfJtXz3RjEE/edit#gid=290888835&range=A1","Open")
...

Sheet Q01
A1: Q01 — Expert Review
A2: Question metadata
A3: Question ID | B3: 1
A4: Topic | B4: Food delivery — market definition
A5: Scope | B5: EU + UK + ES
A6: Original reviewer | B6: Carolina
A7: Original status | B7: Approved
A8: Question | B8: The relevant market in a food-delivery acquisition — how have the Commission and national authorities defined the relevant product and geographic markets, and on what rationales?
A9: Generated answer
A10: Paste the generated answer here.
A11: Run ID | C11: Run date
A12: Retrieval set review
A13: Rank | B13: Document name | C13: Document class | D13: Jurisdiction | E13: URL / Document ID | F13: Required source? | G13: Expert verdict | H13: Notes
A14: 1
A15: 2
A16: 3
A17: 4
A18: 5
A19: 6
A20: 7
A21: 8
A22: 9
A24: Claim-by-claim review
A25: Claim ID | B25: Claim from answer | C25: Cited document | D25: Expert verdict | E25: Cited passage | F25: Required fix / comment
A26: 1
A27: 2
A28: 3
A29: 4
A30: 5
A31: 6
A32: 7
A33: 8
A34: 9
A36: Final expert verdict
A37: Reviewer
A38: Is the answer acceptable?
A39: Overall comment / required fixes
A40: Review completed?

Sheet Lists
A1: A | B1: B | C1: C | D1: D | E1: E | F1: F | G1: G | H1: H
A2: Yes | B2: Not started | C2: Acceptable | D2: Supported | E2: None | F2: Primary law | G2: Yes | H2: Relevant
A3: No | B3: In review | C3: Partly acceptable | D3: Partly supported | E3: Missing source | F3: Concurrences commentary | G3: No | H3: Not relevant
B4: Completed | C4: Not acceptable | D4: Not supported | E4: Wrong citation | F4: Other commentary | G4: Unsure | H4: Duplicate
B5: Needs follow-up | D5: Wrong source | E5: Overclaim | F5: Other | H5: Trap
D6: Missing citation | E6: Unsupported claim | H6: Missing important source
D7: Not a legal claim | E7: Ambiguous wording
E8: Other

Sheet Scoring Summary
A1: Scoring Summary
A2: Team-facing summary. Experts only need to complete the question tabs; this sheet pulls verdicts together.
A4: Question ID | B4: Total claims | C4: Supports claim | D4: Partially supports claim | E4: Does not support claim
A5: 1 | B5: =COUNTA('Q01'!B26:B34) | C5: =COUNTIF('Q01'!D26:D34,"Supports claim") | D5: =COUNTIF('Q01'!D26:D34,"Partially supports claim") | E5: =COUNTIF('Q01'!D26:D34,"Does not support claim")
A6: 2 | B6: =COUNTA('Q02'!B26:B34) | C6: =COUNTIF('Q02'!D26:D34,"Supports claim") | D6: =COUNTIF('Q02'!D26:D34,"Partially supports claim") | E6: =COUNTIF('Q02'!D26:D34,"Does not support claim")
A7: 3 | B7: =COUNTA('Q03'!B26:B34) | C7: =COUNTIF('Q03'!D26:D34,"Supports claim") | D7: =COUNTIF('Q03'!D26:D34,"Partially supports claim") | E7: =COUNTIF('Q03'!D26:D34,"Does not support claim")
A8: 4 | B8: =COUNTA('Q04'!B26:B34) | C8: =COUNTIF('Q04'!D26:D34,"Supports claim") | D8: =COUNTIF('Q04'!D26:D34,"Partially supports claim") | E8: =COUNTIF('Q04'!D26:D34,"Does not support claim")
A9: 5 | B9: =COUNTA('Q05'!B26:B34) | C9: =COUNTIF('Q05'!D26:D34,"Supports claim") | D9: =COUNTIF('Q05'!D26:D34,"Partially supports claim") | E9: =COUNTIF('Q05'!D26:D34,"Does not support claim")
A10: 6 | B10: =COUNTA('Q06'!B26:B34) | C10: =COUNTIF('Q06'!D26:D34,"Supports claim") | D10: =COUNTIF('Q06'!D26:D34,"Partially supports claim") | E10: =COUNTIF('Q06'!D26:D34,"Does not support claim")
A11: 7 | B11: =COUNTA('Q07'!B26:B34) | C11: =COUNTIF('Q07'!D26:D34,"Supports claim") | D11: =COUNTIF('Q07'!D26:D34,"Partially supports claim") | E11: =COUNTIF('Q07'!D26:D34,"Does not support claim")
A12: 8 | B12: =COUNTA('Q08'!B26:B34) | C12: =COUNTIF('Q08'!D26:D34,"Supports claim") | D12: =COUNTIF('Q08'!D26:D34,"Partially supports claim") | E12: =COUNTIF('Q08'!D26:D34,"Does not support claim")
A13: 9 | B13: =COUNTA('Q09'!B26:B34) | C13: =COUNTIF('Q09'!D26:D34,"Supports claim") | D13: =COUNTIF('Q09'!D26:D34,"Partially supports claim") | E13: =COUNTIF('Q09'!D26:D34,"Does not support claim")
A14: 10 | B14: =COUNTA('Q10'!B26:B34) | C14: =COUNTIF('Q10'!D26:D34,"Supports claim") | D14: =COUNTIF('Q10'!D26:D34,"Partially supports claim") | E14: =COUNTIF('Q10'!D26:D34,"Does not support claim")
A15: 11 | B15: =COUNTA('Q11'!B26:B34) | C15: =COUNTIF('Q11'!D26:D34,"Supports claim") | D15: =COUNTIF('Q11'!D26:D34,"Partially supports claim") | E15: =COUNTIF('Q11'!D26:D34,"Does not support claim")
A16: 12 | B16: =COUNTA('Q12'!B26:B34) | C16: =COUNTIF('Q12'!D26:D34,"Supports claim") | D16: =COUNTIF('Q12'!D26:D34,"Partially supports claim") | E16: =COUNTIF('Q12'!D26:D34,"Does not support claim")
A17: 13 | B17: =COUNTA('Q13'!B26:B34) | C17: =COUNTIF('Q13'!D26:D34,"Supports claim") | D17: =COUNTIF('Q13'!D26:D34,"Partially supports claim") | E17: =COUNTIF('Q13'!D26:D34,"Does not support claim")
A18: 14 | B18: =COUNTA('Q14'!B26:B34) | C18: =COUNTIF('Q14'!D26:D34,"Supports claim") | D18: =COUNTIF('Q14'!D26:D34,"Partially supports claim") | E18: =COUNTIF('Q14'!D26:D34,"Does not support claim")
A19: 15 | B19: =COUNTA('Q15'!B26:B34) | C19: =COUNTIF('Q15'!D26:D34,"Supports claim") | D19: =COUNTIF('Q15'!D26:D34,"Partially supports claim") | E19: =COUNTIF('Q15'!D26:D34,"Does not support claim")
A20: 16 | B20: =COUNTA('Q16'!B26:B34) | C20: =COUNTIF('Q16'!D26:D34,"Supports claim") | D20: =COUNTIF('Q16'!D26:D34,"Partially supports claim") | E20: =COUNTIF('Q16'!D26:D34,"Does not support claim")
A21: 17 | B21: =COUNTA('Q17'!B26:B34) | C21: =COUNTIF('Q17'!D26:D34,"Supports claim") | D21: =COUNTIF('Q17'!D26:D34,"Partially supports claim") | E21: =COUNTIF('Q17'!D26:D34,"Does not support claim")
A22: 18 | B22: =COUNTA('Q18'!B26:B34) | C22: =COUNTIF('Q18'!D26:D34,"Supports claim") | D22: =COUNTIF('Q18'!D26:D34,"Partially supports claim") | E22: =COUNTIF('Q18'!D26:D34,"Does not support claim")
A23: 19 | B23: =COUNTA('Q19'!B26:B34) | C23: =COUNTIF('Q19'!D26:D34,"Supports claim") | D23: =COUNTIF('Q19'!D26:D34,"Partially supports claim") | E23: =COUNTIF('Q19'!D26:D34,"Does not support claim")
A24: 20 | B24: =COUNTA('Q20'!B26:B34) | C24: =COUNTIF('Q20'!D26:D34,"Supports claim") | D24: =COUNTIF('Q20'!D26:D34,"Partially supports claim") | E24: =COUNTIF('Q20'!D26:D34,"Does not support claim")
A25: 21 | B25: =COUNTA('Q21'!B26:B34) | C25: =COUNTIF('Q21'!D26:D34,"Supports claim") | D25: =COUNTIF('Q21'!D26:D34,"Partially supports claim") | E25: =COUNTIF('Q21'!D26:D34,"Does not support claim")
A26: 22 | B26: =COUNTA('Q22'!B26:B34) | C26: =COUNTIF('Q22'!D26:D34,"Supports claim") | D26: =COUNTIF('Q22'!D26:D34,"Partially supports claim") | E26: =COUNTIF('Q22'!D26:D34,"Does not support claim")
A27: 23 | B27: =COUNTA('Q23'!B26:B34) | C27: =COUNTIF('Q23'!D26:D34,"Supports claim") | D27: =COUNTIF('Q23'!D26:D34,"Partially supports claim") | E27: =COUNTIF('Q23'!D26:D34,"Does not support claim")
A28: 24 | B28: =COUNTA('Q24'!B26:B34) | C28: =COUNTIF('Q24'!D26:D34,"Supports claim") | D28: =COUNTIF('Q24'!D26:D34,"Partially supports claim") | E28: =COUNTIF('Q24'!D26:D34,"Does not support claim")
A29: 25 | B29: =COUNTA('Q25'!B26:B34) | C29: =COUNTIF('Q25'!D26:D34,"Supports claim") | D29: =COUNTIF('Q25'!D26:D34,"Partially supports claim") | E29: =COUNTIF('Q25'!D26:D34,"Does not support claim")
A30: 26 | B30: =COUNTA('Q26'!B26:B34) | C30: =COUNTIF('Q26'!D26:D34,"Supports claim") | D30: =COUNTIF('Q26'!D26:D34,"Partially supports claim") | E30: =COUNTIF('Q26'!D26:D34,"Does not support claim")
A31: 27 | B31: =COUNTA('Q27'!B26:B34) | C31: =COUNTIF('Q27'!D26:D34,"Supports claim") | D31: =COUNTIF('Q27'!D26:D34,"Partially supports claim") | E31: =COUNTIF('Q27'!D26:D34,"Does not support claim")
A32: 28 | B32: =COUNTA('Q28'!B26:B34) | C32: =COUNTIF('Q28'!D26:D34,"Supports claim") | D32: =COUNTIF('Q28'!D26:D34,"Partially supports claim") | E32: =COUNTIF('Q28'!D26:D34,"Does not support claim")
A33: 29 | B33: =COUNTA('Q29'!B26:B34) | C33: =COUNTIF('Q29'!D26:D34,"Supports claim") | D33: =COUNTIF('Q29'!D26:D34,"Partially supports claim") | E33: =COUNTIF('Q29'!D26:D34,"Does not support claim")
A34: 30 | B34: =COUNTA('Q30'!B26:B34) | C34: =COUNTIF('Q30'!D26:D34,"Supports claim") | D34: =COUNTIF('Q30'!D26:D34,"Partially supports claim") | E34: =COUNTIF('Q30'!D26:D34,"Does not support claim")
A35: 31 | B35: =COUNTA('Q31'!B26:B34) | C35: =COUNTIF('Q31'!D26:D34,"Supports claim") | D35: =COUNTIF('Q31'!D26:D34,"Partially supports claim") | E35: =COUNTIF('Q31'!D26:D34,"Does not support claim")
A36: 32 | B36: =COUNTA('Q32'!B26:B34) | C36: =COUNTIF('Q32'!D26:D34,"Supports claim") | D36: =COUNTIF('Q32'!D26:D34,"Partially supports claim") | E36: =COUNTIF('Q32'!D26:D34,"Does not support claim")
A37: 33 | B37: =COUNTA('Q33'!B26:B34) | C37: =COUNTIF('Q33'!D26:D34,"Supports claim") | D37: =COUNTIF('Q33'!D26:D34,"Partially supports claim") | E37: =COUNTIF('Q33'!D26:D34,"Does not support claim")
A38: 34 | B38: =COUNTA('Q34'!B26:B34) | C38: =COUNTIF('Q34'!D26:D34,"Supports claim") | D38: =COUNTIF('Q34'!D26:D34,"Partially supports claim") | E38: =COUNTIF('Q34'!D26:D34,"Does not support claim")
A39: 35 | B39: =COUNTA('Q35'!B26:B34) | C39: =COUNTIF('Q35'!D26:D34,"Supports claim") | D39: =COUNTIF('Q35'!D26:D34,"Partially supports claim") | E39: =COUNTIF('Q35'!D26:D34,"Does not support claim")
A40: 36 | B40: =COUNTA('Q36'!B26:B34) | C40: =COUNTIF('Q36'!D26:D34,"Supports claim") | D40: =COUNTIF('Q36'!D26:D34,"Partially supports claim") | E40: =COUNTIF('Q36'!D26:D34,"Does not support claim")
A41: 37 | B41: =COUNTA('Q37'!B26:B34) | C41: =COUNTIF('Q37'!D26:D34,"Supports claim") | D41: =COUNTIF('Q37'!D26:D34,"Partially supports claim") | E41: =COUNTIF('Q37'!D26:D34,"Does not support claim")
...

Sheet Q02
A1: Q02 — Expert Review
A2: Question metadata
A3: Question ID | B3: 2
A4: Topic | B4: Food delivery — multi-sided platforms
A5: Scope | B5: EU + UK + ES
A6: Original reviewer | B6: Carolina
A7: Original status | B7: Approved
A8: Question | B8: Food delivery as a multi-sided platform — have authorities analysed these platforms as two- or multi-sided markets, and which sides actually entered the analysis?
A9: Generated answer
A10: Paste the generated answer here.
A11: Run ID | C11: Run date
A12: Retrieval set review
A13: Rank | B13: Document name | C13: Document class | D13: Jurisdiction | E13: URL / Document ID | F13: Required source? | G13: Expert verdict | H13: Notes
A14: 1
A15: 2
A16: 3
A17: 4
A18: 5
A19: 6
A20: 7
A21: 8
A22: 9
A24: Claim-by-claim review
A25: Claim ID | B25: Claim from answer | C25: Cited document | D25: Expert verdict | E25: Cited passage | F25: Required fix / comment
A26: 1
A27: 2
A28: 3
A29: 4
A30: 5
A31: 6
A32: 7
A33: 8
A34: 9
A36: Final expert verdict
A37: Reviewer
A38: Is the answer acceptable?
A39: Overall comment / required fixes
A40: Review completed?
A69: Original source notes
A70: WAB notes
...

Sheet Q03
A1: Q03 — Expert Review
A2: Question metadata
A3: Question ID | B3: 3
A4: Topic | B4: Food delivery — market boundary
A5: Scope | B5: UK (ES colour)
A6: Original reviewer | B6: Carolina
A7: Original status | B7: Approved
A8: Question | B8: Grocery, quick commerce, and the market boundary — separate markets from restaurant meal delivery, or one broad on-demand delivery market?
A9: Generated answer
A10: Paste the generated answer here.
A11: Run ID | C11: Run date
A12: Retrieval set review
A13: Rank | B13: Document name | C13: Document class | D13: Jurisdiction | E13: URL / Document ID | F13: Required source? | G13: Expert verdict | H13: Notes
A14: 1
A15: 2
A16: 3
A17: 4
A18: 5
A19: 6
A20: 7
A21: 8
A22: 9
A24: Claim-by-claim review
A25: Claim ID | B25: Claim from answer | C25: Cited document | D25: Expert verdict | E25: Cited passage | F25: Required fix / comment
A26: 1
A27: 2
A28: 3
A29: 4
A30: 5
A31: 6
A32: 7
A33: 8
A34: 9
A36: Final expert verdict
A37: Reviewer
A38: Is the answer acceptable?
A39: Overall comment / required fixes
A40: Review completed?
A69: Original source notes
A70: WAB notes
...

Sheet Q04
A1: Q04 — Expert Review
A2: Question metadata
A3: Question ID | B3: 4
A4: Topic | B4: Food delivery — failing-firm defence
A5: Scope | B5: UK
A6: Original reviewer | B6: Carolina
A7: Original status | B7: Approved
A8: Question | B8: The failing-firm defence in food delivery — has an exiting-firm counterfactual ever been accepted, did it survive to the final decision, and on what evidence?
A9: Generated answer
A10: Paste the generated answer here.
A11: Run ID | C11: Run date
A12: Retrieval set review
A13: Rank | B13: Document name | C13: Document class | D13: Jurisdiction | E13: URL / Document ID | F13: Required source? | G13: Expert verdict | H13: Notes
A14: 1
A15: 2
A16: 3
A17: 4
A18: 5
A19: 6
A20: 7
A21: 8
A22: 9
A24: Claim-by-claim review
A25: Claim ID | B25: Claim from answer | C25: Cited document | D25: Expert verdict | E25: Cited passage | F25: Required fix / comment
A26: 1
A27: 2
A28: 3
A29: 4
A30: 5
A31: 6
A32: 7
A33: 8
A34: 9
A36: Final expert verdict
A37: Reviewer
A38: Is the answer acceptable?
A39: Overall comment / required fixes
A40: Review completed?
A69: Original source notes
A70: WAB notes
...

Sheet Q05
A1: Q05 — Expert Review
A2: Question metadata
A3: Question ID | B3: 5
A4: Topic | B4: Food delivery — COVID-19
A5: Scope | B5: UK
A6: Original reviewer | B6: Carolina
A7: Original status | B7: Approved
A8: Question | B8: COVID-19 in the competitive assessment — how did the pandemic actually enter the analysis: counterfactual, market definition, or not at all?
A9: Generated answer
A10: Paste the generated answer here.
A11: Run ID | C11: Run date
A12: Retrieval set review
A13: Rank | B13: Document name | C13: Document class | D13: Jurisdiction | E13: URL / Document ID | F13: Required source? | G13: Expert verdict | H13: Notes
A14: 1
A15: 2
A16: 3
A17: 4
A18: 5
A19: 6
A20: 7
A21: 8
A22: 9
A24: Claim-by-claim review
A25: Claim ID | B25: Claim from answer | C25: Cited document | D25: Expert verdict | E25: Cited passage | F25: Required fix / comment
A26: 1
A27: 2
A28: 3
A29: 4
A30: 5
A31: 6
A32: 7
A33: 8
A34: 9
A36: Final expert verdict
A37: Reviewer
A38: Is the answer acceptable?
A39: Overall comment / required fixes
A40: Review completed?
A69: Original source notes
A70: WAB notes
...

Sheet Q06
A1: Q06 — Expert Review
A2: Question metadata
A3: Question ID | B3: 6
A4: Topic | B4: Food delivery — potential competition
A5: Scope | B5: UK
A6: Original reviewer | B6: Carolina
A7: Original status | B7: Approved
A8: Question | B8: Potential competition and re-entry — where the acquirer is not active in the UK, how has the CMA treated entry or re-entry absent the merger?
A9: Generated answer
A10: Paste the generated answer here.
A11: Run ID | C11: Run date
A12: Retrieval set review
A13: Rank | B13: Document name | C13: Document class | D13: Jurisdiction | E13: URL / Document ID | F13: Required source? | G13: Expert verdict | H13: Notes
A14: 1
A15: 2
A16: 3
A17: 4
A18: 5
A19: 6
A20: 7
A21: 8
A22: 9
A24: Claim-by-claim review
A25: Claim ID | B25: Claim from answer | C25: Cited document | D25: Expert verdict | E25: Cited passage | F25: Required fix / comment
A26: 1
A27: 2
A28: 3
A29: 4
A30: 5
A31: 6
A32: 7
A33: 8
A34: 9
A36: Final expert verdict
A37: Reviewer
A38: Is the answer acceptable?
A39: Overall comment / required fixes
A40: Review completed?
A69: Original source notes
A70: WAB notes
...

Sheet Q07
A1: Q07 — Expert Review
A2: Question metadata
A3: Question ID | B3: 7
A4: Topic | B4: Food delivery — no-poach agreements
A5: Scope | B5: EU
A6: Original reviewer | B6: Carolina
A7: Original status | B7: Approved
A8: Question | B8: No-poach agreements under Article 101 — can a reciprocal agreement not to hire each other's staff infringe Article 101, and what is the leading precedent and fine?
A9: Generated answer
A10: Paste the generated answer here.
A11: Run ID | C11: Run date
A12: Retrieval set review
A13: Rank | B13: Document name | C13: Document class | D13: Jurisdiction | E13: URL / Document ID | F13: Required source? | G13: Expert verdict | H13: Notes
A14: 1
A15: 2
A16: 3
A17: 4
A18: 5
A19: 6
A20: 7
A21: 8
A22: 9
A24: Claim-by-claim review
A25: Claim ID | B25: Claim from answer | C25: Cited document | D25: Expert verdict | E25: Cited passage | F25: Required fix / comment
A26: 1
A27: 2
A28: 3
A29: 4
A30: 5
A31: 6
A32: 7
A33: 8
A34: 9
A36: Final expert verdict
A37: Reviewer
A38: Is the answer acceptable?
A39: Overall comment / required fixes
A40: Review completed?
A69: Original source notes
A70: WAB notes
...

Sheet Q08
A1: Q08 — Expert Review
A2: Question metadata
A3: Question ID | B3: 8
A4: Topic | B4: Food delivery — remedies
A5: Scope | B5: EU + UK + ES
A6: Original reviewer | B6: Carolina
A7: Original status | B7: Approved
A8: Question | B8: Remedies in food-delivery mergers — which European reviews ended in remedies or commitments, and what did they look like?
A9: Generated answer
A10: Paste the generated answer here.
A11: Run ID | C11: Run date
A12: Retrieval set review
A13: Rank | B13: Document name | C13: Document class | D13: Jurisdiction | E13: URL / Document ID | F13: Required source? | G13: Expert verdict | H13: Notes
A14: 1
A15: 2
A16: 3
A17: 4
A18: 5
A19: 6
A20: 7
A21: 8
A22: 9
A24: Claim-by-claim review
A25: Claim ID | B25: Claim from answer | C25: Cited document | D25: Expert verdict | E25: Cited passage | F25: Required fix / comment
A26: 1
A27: 2
A28: 3
A29: 4
A30: 5
A31: 6
A32: 7
A33: 8
A34: 9
A36: Final expert verdict
A37: Reviewer
A38: Is the answer acceptable?
A39: Overall comment / required fixes
A40: Review completed?
A69: Original source notes
A70: WAB notes
...

Sheet Q09
A1: Q09 — Expert Review
A2: Question metadata
A3: Question ID | B3: 9
A4: Topic | B4: Food delivery — Spanish practice
A5: Scope | B5: ES
A6: Original reviewer | B6: Carolina
A7: Original status | B7: Approved
A8: Question | B8: The Spanish (CNMC) food-delivery reviews — what is the CNMC's decisional practice, how many cases, and how were they resolved?
A9: Generated answer
A10: Paste the generated answer here.
A11: Run ID | C11: Run date
A12: Retrieval set review
A13: Rank | B13: Document name | C13: Document class | D13: Jurisdiction | E13: URL / Document ID | F13: Required source? | G13: Expert verdict | H13: Notes
A14: 1
A15: 2
A16: 3
A17: 4
A18: 5
A19: 6
A20: 7
A21: 8
A22: 9
A24: Claim-by-claim review
A25: Claim ID | B25: Claim from answer | C25: Cited document | D25: Expert verdict | E25: Cited passage | F25: Required fix / comment
A26: 1
A27: 2
A28: 3
A29: 4
A30: 5
A31: 6
A32: 7
A33: 8
A34: 9
A36: Final expert verdict
A37: Reviewer
A38: Is the answer acceptable?
A39: Overall comment / required fixes
A40: Review completed?
A69: Original source notes
A70: WAB notes
...

Sheet Q10
A1: Q10 — Expert Review
A2: Question metadata
A3: Question ID | B3: 10
A4: Topic | B4: Food delivery — minority shareholdings
A5: Scope | B5: EU + UK
A6: Original reviewer | B6: Carolina
A7: Original status | B7: Approved
A8: Question | B8: Material influence and minority shareholdings — on what basis did the CMA take jurisdiction over a c.16% stake, and how else have authorities treated minority shareholdings in merger control?
A9: Generated answer
A10: Paste the generated answer here.
A11: Run ID | C11: Run date
A12: Retrieval set review
A13: Rank | B13: Document name | C13: Document class | D13: Jurisdiction | E13: URL / Document ID | F13: Required source? | G13: Expert verdict | H13: Notes
A14: 1
A15: 2
A16: 3
A17: 4
A18: 5
A19: 6
A20: 7
A21: 8
A22: 9
A24: Claim-by-claim review
A25: Claim ID | B25: Claim from answer | C25: Cited document | D25: Expert verdict | E25: Cited passage | F25: Required fix / comment
A26: 1
A27: 2
A28: 3
A29: 4
A30: 5
A31: 6
A32: 7
A33: 8
A34: 9
A36: Final expert verdict
A37: Reviewer
A38: Is the answer acceptable?
A39: Overall comment / required fixes
A40: Review completed?
A69: Original source notes
A70: WAB notes
...

Sheet Q11
A1: Q11 — Expert Review
A2: Question metadata
A3: Question ID | B3: 11
A4: Topic | B4: Food delivery — evolution of practice
A5: Scope | B5: EU + UK + ES
A6: Original reviewer | B6: Carolina
A7: Original status | B7: Approved
A8: Question | B8: The evolution of European food-delivery merger control, 2017–2025 — how has practice evolved from the first national marketplace consolidations to the recent Commission decisions?
A9: Generated answer
A10: Paste the generated answer here.
A11: Run ID | C11: Run date
A12: Retrieval set review
A13: Rank | B13: Document name | C13: Document class | D13: Jurisdiction | E13: URL / Document ID | F13: Required source? | G13: Expert verdict | H13: Notes
A14: 1
A15: 2
A16: 3
A17: 4
A18: 5
A19: 6
A20: 7
A21: 8
A22: 9
A24: Claim-by-claim review
A25: Claim ID | B25: Claim from answer | C25: Cited document | D25: Expert verdict | E25: Cited passage | F25: Required fix / comment
A26: 1
A27: 2
A28: 3
A29: 4
A30: 5
A31: 6
A32: 7
A33: 8
A34: 9
A36: Final expert verdict
A37: Reviewer
A38: Is the answer acceptable?
A39: Overall comment / required fixes
A40: Review completed?
A69: Original source notes
A70: WAB notes
...

Sheet Q12
A1: Q12 — Expert Review
A2: Question metadata
A3: Question ID | B3: 12
A4: Topic | B4: Dawn raids — legal professional privilege
A5: Scope | B5: France
A6: Original reviewer | B6: Carolina
A7: Original status | B7: Approved
A8: Question | B8: At what stage is attorney-client privilege breached during a dawn raid — when the inspector reads the document, or only when it is later used?
A9: Generated answer
A10: Paste the generated answer here.
A11: Run ID | C11: Run date
A12: Retrieval set review
A13: Rank | B13: Document name | C13: Document class | D13: Jurisdiction | E13: URL / Document ID | F13: Required source? | G13: Expert verdict | H13: Notes
A14: 1
A15: 2
A16: 3
A17: 4
A18: 5
A19: 6
A20: 7
A21: 8
A22: 9
A24: Claim-by-claim review
A25: Claim ID | B25: Claim from answer | C25: Cited document | D25: Expert verdict | E25: Cited passage | F25: Required fix / comment
A26: 1
A27: 2
A28: 3
A29: 4
A30: 5
A31: 6
A32: 7
A33: 8
A34: 9
A36: Final expert verdict
A37: Reviewer
A38: Is the answer acceptable?
A39: Overall comment / required fixes
A40: Review completed?
A69: Original source notes
A70: WAB notes | B70: Your wording, unchanged. We had drafted a wider French question instead — how correspondence between a company and its lawyer is protected, how a seizure of it is contested, and whether the remedy is return, destruction or exclusion from the file. We put yours back because it is sharper. Tell us if you want the wider version, or both.
...

Sheet Q13
A1: Q13 — Expert Review
A2: Question metadata
A3: Question ID | B3: 13
A4: Topic | B4: Dawn raids — personal data
A5: Scope | B5: France
A6: Original reviewer | B6: Carolina
A7: Original status | B7: Approved
A8: Question | B8: Under what conditions must the Competition Authority protect personal data during a dawn raid? Does the GDPR apply? Must documents be sealed on request?
A9: Generated answer
A10: Paste the generated answer here.
A11: Run ID | C11: Run date
A12: Retrieval set review
A13: Rank | B13: Document name | C13: Document class | D13: Jurisdiction | E13: URL / Document ID | F13: Required source? | G13: Expert verdict | H13: Notes
A14: 1
A15: 2
A16: 3
A17: 4
A18: 5
A19: 6
A20: 7
A21: 8
A22: 9
A24: Claim-by-claim review
A25: Claim ID | B25: Claim from answer | C25: Cited document | D25: Expert verdict | E25: Cited passage | F25: Required fix / comment
A26: 1
A27: 2
A28: 3
A29: 4
A30: 5
A31: 6
A32: 7
A33: 8
A34: 9
A36: Final expert verdict
A37: Reviewer
A38: Is the answer acceptable?
A39: Overall comment / required fixes
A40: Review completed?
A69: Original source notes
A70: WAB notes | B70: Your wording, unchanged.
...

Sheet Q14
A1: Q14 — Expert Review
A2: Question metadata
A3: Question ID | B3: 14
A4: Topic | B4: Dawn raids — challenging a seizure
A5: Scope | B5: France
A6: Original reviewer | B6: Carolina
A7: Original status | B7: Approved
A8: Question | B8: After a dawn raid, can the President of the Court of Appeal be seized in interim proceedings to urgently resolve attorney-client privilege disputes? On what legal basis and under what conditions?
A9: Generated answer
A10: Paste the generated answer here.
A11: Run ID | C11: Run date
A12: Retrieval set review
A13: Rank | B13: Document name | C13: Document class | D13: Jurisdiction | E13: URL / Document ID | F13: Required source? | G13: Expert verdict | H13: Notes
A14: 1
A15: 2
A16: 3
A17: 4
A18: 5
A19: 6
A20: 7
A21: 8
A22: 9
A24: Claim-by-claim review
A25: Claim ID | B25: Claim from answer | C25: Cited document | D25: Expert verdict | E25: Cited passage | F25: Required fix / comment
A26: 1
A27: 2
A28: 3
A29: 4
A30: 5
A31: 6
A32: 7
A33: 8
A34: 9
A36: Final expert verdict
A37: Reviewer
A38: Is the answer acceptable?
A39: Overall comment / required fixes
A40: Review completed?
A69: Original source notes
A70: WAB notes | B70: Your wording, unchanged. One point to check: we understand Article L.450-4 of the Code de commerce to designate the FIRST President of the Court of Appeal (premier président), not the President. We have left your wording and are raising it rather than correcting it.
...

Sheet Q15
A1: Q15 — Expert Review
A2: Question metadata
A3: Question ID | B3: 15
A4: Topic | B4: Dawn raids — legal professional privilege
A5: Scope | B5: EU
A6: Original reviewer | B6: Carolina
A7: Original status | B7: Approved
A8: Question | B8: At what stage is attorney-client privilege breached during a European Commission inspection under Article 20 of Regulation 1/2003 — when the inspector reads the document, or only when the Commission later uses it?
A9: Generated answer
A10: Paste the generated answer here.
A11: Run ID | C11: Run date
A12: Retrieval set review
A13: Rank | B13: Document name | C13: Document class | D13: Jurisdiction | E13: URL / Document ID | F13: Required source? | G13: Expert verdict | H13: Notes
A14: 1 | B14: inspections-eu-law-2nd--3_chapter_1_-_inspections_upon_decision_regulation_1_2003_article_20_4.md | C14: Book (Livre) | E14: d28b1d20-a2c6-425f-a401-498eab28d744
A15: 2 | B15: eu-antitrust-enforcement--14_xiii_legal_professional_privilege_in_eu_antitrust_enforcement_law_policy_and_procedure.md | C15: Book (Livre) | E15: 751159c7-e8b0-4cba-8ae1-5652058d7980 | H15: Cited in answer: YES
A16: 3 | B16: 62020CC0682.md | C16: Article (Review) | D16: EU | E16: f6fc977b-8c8d-467b-a5f7-04beb77f1b93 | H16: Cited in answer: YES
A17: 4 | B17: 62017TJ0249.md | C17: Court Decision | D17: EU | E17: dbf7bda8-39fa-4eb5-a6e2-f02b0787cb54
A18: 5 | B18: eu-antitrust-enforcement--11_x_fundamental_procedural_rights_and_effective_enforcement_of_articles_101_and_102_tfeu_in_the_european_competition_network.md | C18: Book (Livre) | E18: 44d971b2-9615-45f5-94c3-342633964481
A19: 6 | B19: 62018CJ0403.md | C19: Court Decision | D19: EU | E19: 5b155c4b-0345-4afa-8dee-d56351895c8f
A20: 7 | B20: eu-antitrust-enforcement--12_xi_the_role_of_the_hearing_officer_in_antitrust_proceedings_before_the_european_commission.md | C20: Book (Livre) | E20: 27d55d8c-5b59-43c1-8576-7a718bd009d4
A21: 8 | B21: 121144.md | C21: Bulletin article | E21: 9f96a5ff-2537-45cd-a34f-b0f82767f132
A22: 9 | B22: 62020CJ0693.md | C22: Court Decision | D22: EU | E22: 74ccf3f4-5d27-4c74-9208-62829cc5bcf1
A23: 10 | B23: 62023TJ1097.md | C23: Court Decision | D23: EU | E23: 17ecc724-b05f-4f42-9a28-b1282ba34327
A24: 11 | B24: 67860.md | C24: Bulletin article | E24: f3b54f3e-52e4-4232-8e7a-129fe9239fec
A25: 12 | B25: 62007CJ0550.md | C25: Court Decision | D25: EU | E25: 77a4dd19-04ce-410f-ba8e-9998f2902880 | H25: Cited in answer: YES
A26: 13 | B26: 62020CC0682.md | C26: Bulletin article | D26: EU | E26: 4228e89d-bc15-4a00-9ed7-bd703f8ec05a | H26: Cited in answer: YES
A27: 14 | B27: 61979CJ0155.md | C27: Court Decision | D27: EU | E27: 5353da9e-012f-4409-bde2-d1256386ccb7 | H27: Cited in answer: YES
A28: 15 | B28: AT.40588-DEC_3BB0CA7D-3722-43A5-85E8-BF3CA6EB441B_-ATT6339.md | C28: Regulatory Decision | D28: EU | E28: 9d692a02-4ebd-41a5-ae70-af412829d83f
A29: 16 | B29: 62023TJ1097.md | C29: Court Decision | D29: EU | E29: 19135079-d5db-4c66-b2d1-4bc35297af23
A30: 17 | B30: 91835.md | C30: Article (Review) | E30: f6ec0179-d152-4059-9a3f-81d669d422b0
A31: 18 | B31: 62003TJ0125.md | C31: Court Decision | D31: EU | E31: a8c1d5f4-d4fb-4365-bf78-e327971748f9 | H31: Cited in answer: YES
A32: 19 | B32: 62020CJ0682.md | C32: Court Decision | D32: EU | E32: 408cfe67-7fe4-45a8-9c3e-de39d86d56cb
A33: 20 | B33: 62020CJ0690.md | C33: Court Decision | D33: EU | E33: 75c2da13-00ee-43b2-baa4-a6f2e5a71e73
A34: 21 | B34: compendium-eu-competition-law--p20.md | C34: Legislation | E34: 4051fc69-a489-4b05-95ab-16bd651b54f1
A35: 22 | B35: AT.37990-DEC_D1115C27-9B1D-401A-A930-8895EBEFC8F6_-ATT3581.md | C35: Regulatory Decision | D35: EU | E35: b320e5cc-5605-4cb5-9f85-f6decae603d2
A36: 23 | B36: 96586.md | C36: Article (Review) | E36: 4cb5c154-4d3a-46c3-8bca-8f09c7e6c562
A37: 24 | B37: 41554.md | C37: Bulletin article | E37: 7ac322df-dba5-454b-a0e6-0bff2167a703
A38: 25 | B38: 62020TJ0451.md | C38: Court Decision | D38: EU | E38: 48c42881-8462-4197-885e-35fd7e697950
A39: 26 | B39: judicial-review-competition-cases--6_european_union_-_judicial_review_of_inspection_decisions.md | C39: Article (Review) | E39: 21a3ec2e-1c42-4307-ab97-e45011d6660a
A40: 27 | B40: AT.38589-DEC_3E35814B-057B-4DBA-846C-7E857FD065EA_-ATT4669.md | C40: Regulatory Decision | D40: EU | E40: 4c1b86f8-9f04-46e8-acde-128a983395c5
...

Sheet Q16
A1: Q16 — Expert Review
A2: Question metadata
A3: Question ID | B3: 16
A4: Topic | B4: Dawn raids — personal data
A5: Scope | B5: EU
A6: Original reviewer | B6: Carolina
A7: Original status | B7: Approved
A8: Question | B8: Under what conditions must the European Commission protect personal data during an inspection? Does the GDPR apply? Must documents be sealed on request?
A9: Generated answer
A10: Paste the generated answer here.
A11: Run ID | C11: Run date
A12: Retrieval set review
A13: Rank | B13: Document name | C13: Document class | D13: Jurisdiction | E13: URL / Document ID | F13: Required source? | G13: Expert verdict | H13: Notes
A14: 1 | B14: inspections-eu-law-2nd--3_chapter_1_-_inspections_upon_decision_regulation_1_2003_article_20_4.md | C14: Book (Livre) | E14: d28b1d20-a2c6-425f-a401-498eab28d744
A15: 2 | B15: 32018D1927.md | C15: Legislation | D15: EU | E15: 4b2f4063-4380-45e9-a0c5-38939bcc1d22 | H15: Cited in answer: YES
A16: 3 | B16: 62020TO0451(01).md | C16: Court Decision | D16: EU | E16: b261ed51-2a85-4d85-a20a-92143a7cd6a5 | H16: Cited in answer: YES
A17: 4 | B17: 62020TO0452(01).md | C17: Court Decision | D17: EU | E17: 2768689e-df78-453e-8a77-732820fda1c8
A18: 5 | B18: 62023TJ1097.md | C18: Court Decision | D18: EU | E18: 17ecc724-b05f-4f42-9a28-b1282ba34327
A19: 6 | B19: 62023TJ1119.md | C19: Court Decision | D19: EU | E19: ce0e3df2-f4ea-4345-a297-e54a4f805a9f
A20: 7 | B20: eu-antitrust-enforcement--15_xiv_procedural_rights_and_obligations_of_third_parties_in_antitrust_investigations_and_proceedings_by_the_european_commission.md | C20: Book (Livre) | E20: b2429dd2-ef75-4f34-8bf2-95b08c3a4de5
A21: 8 | B21: 128250-35-dawn-raids-the-general-court-of-the-european-union-partially-upholds-the-lega.md | C21: Bulletin article | E21: e34c0e6d-2771-4073-8165-4a73eff42d4c
A22: 9 | B22: 62020TJ0451.md | C22: Court Decision | D22: EU | E22: 48c42881-8462-4197-885e-35fd7e697950
A23: 10 | B23: 97110-2850-inspection-the-general-court-of-the-european-union-partially-annuls-decisio.md | C23: Bulletin article | E23: 0ff86075-a215-4bce-ac53-21a9aa21cd71
A24: 11 | B24: 125471-20-dawn-raids-the-general-court-upholds-the-european-commissions-overall-assessm.md | C24: Bulletin article | E24: e97ed81a-60ca-4112-9207-21a8613078bd
A25: 12 | B25: 62020TJ0452.md | C25: Court Decision | D25: EU | E25: b2ad17a9-5061-42da-938b-6bc18c4c1e54
A26: 13 | B26: 131688-30-inspections-the-general-court-of-the-european-union-upholds-the-european-comm.md | C26: Bulletin article | E26: 7de191c9-0221-423b-b670-ef1e047a0196
A27: 14 | B27: 57935-361-decisions-adopted-during-an-inspection-the-general-court-reminds-the-commiss.md | C27: Bulletin article | E27: 882aa354-e6cf-464a-b1e2-9486b1cca48f
A28: 15 | B28: competition-inspections-25-jurisdictions--7_european_union.md | C28: Article (Review) | E28: 1c2fa592-34f0-4656-96c2-024c5ea88b1e | H28: Cited in answer: YES
A29: 16 | B29: 96586.md | C29: Article (Review) | E29: 4cb5c154-4d3a-46c3-8bca-8f09c7e6c562
A30: 17 | B30: eu-antitrust-enforcement--16_xv_publication_of_antitrust_decisions_of_the_european_commission.md | C30: Book (Livre) | E30: 3c9799ff-7e91-4daf-9fef-671444f16757
A31: 18 | B31: 32019D1862.md | C31: Legislation | D31: EU | E31: b5b6f4c2-f369-46e5-a382-72fbc8df883a
A32: 19 | B32: 32022R1925.md | C32: Legislation | D32: EU | E32: 2bb20ffc-93ba-4ba0-8872-0bbfc5b98609
A33: 20 | B33: 32024R1689.md | C33: Legislation | D33: EU | E33: d164805a-0886-4c4e-933f-d963ad9182ea
A34: 21 | B34: competition-case-law-digest-5th--p09.md | C34: Book (Livre) | E34: 2f0afdb0-43c8-41b3-99e2-c3003ab906c1
A35: 22 | B35: 103260-35-necessary-limits-to-the-commission-s-inspection-powers.md | C35: Article (Review) | E35: bef18b4b-bb03-49c0-a7aa-afed485ec5d2
A36: 23 | B36: 127929-the-eu-general-court-upholds-the-commissions-inspection-methodology-based-on-pub.md | C36: Bulletin article | E36: af2e8c94-00c3-40d4-8e35-233542ca536d
A37: 24 | B37: 32018R1725.md | C37: Legislation | D37: EU | E37: bc2299a1-c240-4a91-aa11-b5bd00c815b5
A38: 25 | B38: 32025R0327.md | C38: Legislation | D38: EU | E38: 10cab083-f284-482e-8d36-a5faf47762ab
A39: 26 | B39: 127186-20-inspection-the-general-court-of-the-european-union-considers-that-the-commiss.md | C39: Bulletin article | E39: 329bd68b-1104-4f5c-b636-e9925175dbc6
A40: 27 | B40: 62023TJ1097.md | C40: Court Decision | D40: EU | E40: 19135079-d5db-4c66-b2d1-4bc35297af23
...

Sheet Q17
A1: Q17 — Expert Review
A2: Question metadata
A3: Question ID | B3: 17
A4: Topic | B4: Dawn raids — challenging a seizure
A5: Scope | B5: EU
A6: Original reviewer | B6: Carolina
A7: Original status | B7: Approved
A8: Question | B8: What procedural avenues exist to challenge seizure of privileged documents after a European Commission inspection?
A9: Generated answer
A10: Paste the generated answer here.
A11: Run ID | C11: Run date
A12: Retrieval set review
A13: Rank | B13: Document name | C13: Document class | D13: Jurisdiction | E13: URL / Document ID | F13: Required source? | G13: Expert verdict | H13: Notes
A14: 1 | B14: inspections-eu-law-2nd--3_chapter_1_-_inspections_upon_decision_regulation_1_2003_article_20_4.md | C14: Book (Livre) | E14: d28b1d20-a2c6-425f-a401-498eab28d744
A15: 2 | B15: 62018CJ0403.md | C15: Court Decision | D15: EU | E15: 5b155c4b-0345-4afa-8dee-d56351895c8f
A16: 3 | B16: 129921.md | C16: Article (Review) | E16: f778c4be-e8ad-469a-a0b4-810de049896e
A17: 4 | B17: judicial-review-competition-cases--6_european_union_-_judicial_review_of_inspection_decisions.md | C17: Article (Review) | E17: 21a3ec2e-1c42-4307-ab97-e45011d6660a | H17: Cited in answer: YES
A18: 5 | B18: 62023TJ1097.md | C18: Court Decision | D18: EU | E18: 17ecc724-b05f-4f42-9a28-b1282ba34327
A19: 6 | B19: competition-case-law-digest-5th--p10.md | C19: Book (Livre) | E19: 65e060cb-bdeb-413d-b4e8-b9ffe0ed3995
A20: 7 | B20: 131688-30-inspections-the-general-court-of-the-european-union-upholds-the-european-comm.md | C20: Bulletin article | E20: 7de191c9-0221-423b-b670-ef1e047a0196
A21: 8 | B21: judicial-review-competition-cases--7_european_union_-_are_there_any_limits_to_unlimited_jurisdiction_judicial_review_of_commission_discretion_in_setting_fines_for_breaches_of_eu_competition_rules.md | C21: Article (Review) | E21: db161723-dcab-4880-a411-5ede0c406c3a
A22: 9 | B22: 62020CC0682.md | C22: Article (Review) | D22: EU | E22: f6fc977b-8c8d-467b-a5f7-04beb77f1b93
A23: 10 | B23: 128250-35-dawn-raids-the-general-court-of-the-european-union-partially-upholds-the-lega.md | C23: Bulletin article | E23: e34c0e6d-2771-4073-8165-4a73eff42d4c
A24: 11 | B24: 97110-2850-inspection-the-general-court-of-the-european-union-partially-annuls-decisio.md | C24: Bulletin article | E24: 0ff86075-a215-4bce-ac53-21a9aa21cd71
A25: 12 | B25: eu-antitrust-enforcement--12_xi_the_role_of_the_hearing_officer_in_antitrust_proceedings_before_the_european_commission.md | C25: Book (Livre) | E25: 27d55d8c-5b59-43c1-8576-7a718bd009d4 | H25: Cited in answer: YES
A26: 13 | B26: 91835.md | C26: Article (Review) | E26: f6ec0179-d152-4059-9a3f-81d669d422b0
A27: 14 | B27: 125471-20-dawn-raids-the-general-court-upholds-the-european-commissions-overall-assessm.md | C27: Bulletin article | E27: e97ed81a-60ca-4112-9207-21a8613078bd
A28: 15 | B28: 93706-0060-dawn-raids-advocate-general-kokott-calls-on-the-court-of-justice-to-uphold.md | C28: Bulletin article | E28: 42a1613c-b25b-476e-a3b4-e1cac9b5add2
A29: 16 | B29: 57935-361-decisions-adopted-during-an-inspection-the-general-court-reminds-the-commiss.md | C29: Bulletin article | E29: 882aa354-e6cf-464a-b1e2-9486b1cca48f
A30: 17 | B30: 62017TJ0249.md | C30: Court Decision | D30: EU | E30: dbf7bda8-39fa-4eb5-a6e2-f02b0787cb54
A31: 18 | B31: eu-antitrust-enforcement--15_xiv_procedural_rights_and_obligations_of_third_parties_in_antitrust_investigations_and_proceedings_by_the_european_commission.md | C31: Book (Livre) | E31: b2429dd2-ef75-4f34-8bf2-95b08c3a4de5
A32: 19 | B32: eu-antitrust-enforcement--14_xiii_legal_professional_privilege_in_eu_antitrust_enforcement_law_policy_and_procedure.md | C32: Book (Livre) | E32: 751159c7-e8b0-4cba-8ae1-5652058d7980 | H32: Cited in answer: YES
A33: 20 | B33: 62007CJ0550.md | C33: Court Decision | D33: EU | E33: 77a4dd19-04ce-410f-ba8e-9998f2902880 | H33: Cited in answer: YES
A34: 21 | B34: 121144.md | C34: Bulletin article | E34: 9f96a5ff-2537-45cd-a34f-b0f82767f132
A35: 22 | B35: 79963.md | C35: Article (Review) | E35: b0c5f913-948d-4dcc-9ea4-98f6136ca5a7
A36: 23 | B36: 96845-the-eu-court-of-justice-rules-that-legal-professional-privilege-does-not-cover-c.md | C36: Bulletin article | E36: ffcd147d-9482-4eff-8ba1-f4eafa068ea6
A37: 24 | B37: 62020CJ0682.md | C37: Court Decision | D37: EU | E37: 408cfe67-7fe4-45a8-9c3e-de39d86d56cb
A38: 25 | B38: 62023TJ1097.md | C38: Court Decision | D38: EU | E38: 19135079-d5db-4c66-b2d1-4bc35297af23
A39: 26 | B39: 62003TJ0125.md | C39: Court Decision | D39: EU | E39: a8c1d5f4-d4fb-4365-bf78-e327971748f9 | H39: Cited in answer: YES
A40: 27 | B40: 95849-3360-inspections-the-court-of-justice-of-the-european-union-gives-the-commission.md | C40: Bulletin article | E40: afe07022-9e8e-4270-a8d4-2c0aaa70652f
...

Sheet Q18
A1: Q18 — Expert Review
A2: Question metadata
A3: Question ID | B3: 18
A4: Topic | B4: Dawn raids — legal professional privilege
A5: Scope | B5: US
A6: Original reviewer | B6: Arthur
A7: Original status | B7: Approved
A8: Question | B8: At what stage is attorney-client privilege breached when US antitrust authorities gather documents — when the investigator reads the document, or only when it is later used?
A9: Generated answer
A10: Paste the generated answer here.
A11: Run ID | C11: Run date
A12: Retrieval set review
A13: Rank | B13: Document name | C13: Document class | D13: Jurisdiction | E13: URL / Document ID | F13: Required source? | G13: Expert verdict | H13: Notes
A14: 1
A15: 2
A16: 3
A17: 4
A18: 5
A19: 6
A20: 7
A21: 8
A22: 9
A24: Claim-by-claim review
A25: Claim ID | B25: Claim from answer | C25: Cited document | D25: Expert verdict | E25: Cited passage | F25: Required fix / comment
A26: 1
A27: 2
A28: 3
A29: 4
A30: 5
A31: 6
A32: 7
A33: 8
A34: 9
A36: Final expert verdict
A37: Reviewer
A38: Is the answer acceptable?
A39: Overall comment / required fixes
A40: Review completed?
A69: Original source notes
A70: WAB notes | B70: Your document gave this as "the same attorney-client privilege question transposed to US inspections". This is our wording of it. We had drafted a wider US question instead — how privilege is protected, what separates a criminal search from civil compulsory process, and what keeps privileged material away from the investigating team. Yours is narrower and sharper, so we used yours. Tell us if you want the wider version, or both.
...

Sheet Q19
A1: Q19 — Expert Review
A2: Question metadata
A3: Question ID | B3: 19
A4: Topic | B4: Dawn raids — personal data
A5: Scope | B5: US
A6: Original reviewer | B6: Arthur
A7: Original status | B7: Approved
A8: Question | B8: What protections apply to personal or otherwise sensitive data gathered by U.S. antitrust authorities, and on what grounds may material that is irrelevant, overbroad, privileged, or otherwise protected be segregated, withheld, returned, or destroyed?
A9: Generated answer
A10: Paste the generated answer here.
A11: Run ID | C11: Run date
