Workbook

Sheet README
A1: Concurrences Gate 2 Expert Review Template
A3: Purpose | B3: This workbook is for reviewing generated answers and retrieved sources for Approved benchmark questions only.
A5: How experts should use this file
A6: 1. Open the tab for your question, for example Q01.
A7: 2. Review the generated answer and the sources retrieved by the system.
A8: 3. For each legal claim, mark whether the cited source supports it.
A9: 4. Add a short comment only where something must be fixed or clarified.
A10: 5. Mark the final expert verdict at the bottom of each question tab.
A11: 6. The team will use Review Status and Scoring Summary to track progress and calculate metrics.
A14: Key dates
A15: Answers and retrieval sets generated by | B15: 2026-08-14
A16: Expert claim-by-claim review completed by | B16: 2026-08-21

Sheet Lists
A1: A | B1: B | C1: C | D1: D | E1: E | F1: F | G1: G | H1: H
A2: Yes | B2: Not started | C2: Acceptable | D2: Supported | E2: None | F2: Primary law | G2: Yes | H2: Relevant
A3: No | B3: In review | C3: Partly acceptable | D3: Partly supported | E3: Missing source | F3: Concurrences commentary | G3: No | H3: Not relevant
B4: Completed | C4: Not acceptable | D4: Not supported | E4: Wrong citation | F4: Other commentary | G4: Unsure | H4: Duplicate
B5: Needs follow-up | D5: Wrong source | E5: Overclaim | F5: Other | H5: Trap
D6: Missing citation | E6: Unsupported claim | H6: Missing important source
D7: Not a legal claim | E7: Ambiguous wording
E8: Other

Sheet Review Status
A1: Review Status
A3: Question ID | B3: Topic | C3: Scope | D3: Question | E3: Answer generated? | F3: Retrieval set generated? | G3: Expert review status | H3: Reviewer | I3: Completed date | J3: Final verdict | K3: Main issue / follow-up | L3: Question tab | M3: Open tab
A4: 1 | B4: Food delivery — market definition | C4: EU + UK + ES | D4: The relevant market in a food-delivery acquisition — how have the Commission and national authorities defined the relevant product and geographic markets, and on what rationales? | E4: =IF(LEN('Q01'!A16)>0,"Yes","No") | F4: =IF(COUNTA('Q01'!B21:B35)>0,"Yes","No") | G4: =IF('Q01'!B66="Yes","Completed",IF(COUNTA('Q01'!D39:D58)>0,"In review","Not started")) | H4: ='Q01'!B67 | I4: ='Q01'!D67 | J4: ='Q01'!B61 | K4: ='Q01'!B62 | L4: Q01 | M4: Open tab
A5: 2 | B5: Food delivery — multi-sided platforms | C5: EU + UK + ES | D5: Food delivery as a multi-sided platform — have authorities analysed these platforms as two- or multi-sided markets, and which sides actually entered the analysis? | E5: =IF(LEN('Q02'!A16)>0,"Yes","No") | F5: =IF(COUNTA('Q02'!B21:B35)>0,"Yes","No") | G5: =IF('Q02'!B66="Yes","Completed",IF(COUNTA('Q02'!D39:D58)>0,"In review","Not started")) | H5: ='Q02'!B67 | I5: ='Q02'!D67 | J5: ='Q02'!B61 | K5: ='Q02'!B62 | L5: Q02 | M5: Open tab
A6: 3 | B6: Food delivery — market boundary | C6: UK (ES colour) | D6: Grocery, quick commerce, and the market boundary — separate markets from restaurant meal delivery, or one broad on-demand delivery market? | E6: =IF(LEN('Q03'!A16)>0,"Yes","No") | F6: =IF(COUNTA('Q03'!B21:B35)>0,"Yes","No") | G6: =IF('Q03'!B66="Yes","Completed",IF(COUNTA('Q03'!D39:D58)>0,"In review","Not started")) | H6: ='Q03'!B67 | I6: ='Q03'!D67 | J6: ='Q03'!B61 | K6: ='Q03'!B62 | L6: Q03 | M6: Open tab
A7: 4 | B7: Food delivery — failing-firm defence | C7: UK | D7: The failing-firm defence in food delivery — has an exiting-firm counterfactual ever been accepted, did it survive to the final decision, and on what evidence? | E7: =IF(LEN('Q04'!A16)>0,"Yes","No") | F7: =IF(COUNTA('Q04'!B21:B35)>0,"Yes","No") | G7: =IF('Q04'!B66="Yes","Completed",IF(COUNTA('Q04'!D39:D58)>0,"In review","Not started")) | H7: ='Q04'!B67 | I7: ='Q04'!D67 | J7: ='Q04'!B61 | K7: ='Q04'!B62 | L7: Q04 | M7: Open tab
A8: 5 | B8: Food delivery — COVID-19 | C8: UK | D8: COVID-19 in the competitive assessment — how did the pandemic actually enter the analysis: counterfactual, market definition, or not at all? | E8: =IF(LEN('Q05'!A16)>0,"Yes","No") | F8: =IF(COUNTA('Q05'!B21:B35)>0,"Yes","No") | G8: =IF('Q05'!B66="Yes","Completed",IF(COUNTA('Q05'!D39:D58)>0,"In review","Not started")) | H8: ='Q05'!B67 | I8: ='Q05'!D67 | J8: ='Q05'!B61 | K8: ='Q05'!B62 | L8: Q05 | M8: Open tab
A9: 6 | B9: Food delivery — potential competition | C9: UK | D9: Potential competition and re-entry — where the acquirer is not active in the UK, how has the CMA treated entry or re-entry absent the merger? | E9: =IF(LEN('Q06'!A16)>0,"Yes","No") | F9: =IF(COUNTA('Q06'!B21:B35)>0,"Yes","No") | G9: =IF('Q06'!B66="Yes","Completed",IF(COUNTA('Q06'!D39:D58)>0,"In review","Not started")) | H9: ='Q06'!B67 | I9: ='Q06'!D67 | J9: ='Q06'!B61 | K9: ='Q06'!B62 | L9: Q06 | M9: Open tab
A10: 7 | B10: Food delivery — no-poach agreements | C10: EU | D10: No-poach agreements under Article 101 — can a reciprocal agreement not to hire each other's staff infringe Article 101, and what is the leading precedent and fine? | E10: =IF(LEN('Q07'!A16)>0,"Yes","No") | F10: =IF(COUNTA('Q07'!B21:B35)>0,"Yes","No") | G10: =IF('Q07'!B66="Yes","Completed",IF(COUNTA('Q07'!D39:D58)>0,"In review","Not started")) | H10: ='Q07'!B67 | I10: ='Q07'!D67 | J10: ='Q07'!B61 | K10: ='Q07'!B62 | L10: Q07 | M10: Open tab
A11: 8 | B11: Food delivery — remedies | C11: EU + UK + ES | D11: Remedies in food-delivery mergers — which European reviews ended in remedies or commitments, and what did they look like? | E11: =IF(LEN('Q08'!A16)>0,"Yes","No") | F11: =IF(COUNTA('Q08'!B21:B35)>0,"Yes","No") | G11: =IF('Q08'!B66="Yes","Completed",IF(COUNTA('Q08'!D39:D58)>0,"In review","Not started")) | H11: ='Q08'!B67 | I11: ='Q08'!D67 | J11: ='Q08'!B61 | K11: ='Q08'!B62 | L11: Q08 | M11: Open tab
A12: 9 | B12: Food delivery — Spanish practice | C12: ES | D12: The Spanish (CNMC) food-delivery reviews — what is the CNMC's decisional practice, how many cases, and how were they resolved? | E12: =IF(LEN('Q09'!A16)>0,"Yes","No") | F12: =IF(COUNTA('Q09'!B21:B35)>0,"Yes","No") | G12: =IF('Q09'!B66="Yes","Completed",IF(COUNTA('Q09'!D39:D58)>0,"In review","Not started")) | H12: ='Q09'!B67 | I12: ='Q09'!D67 | J12: ='Q09'!B61 | K12: ='Q09'!B62 | L12: Q09 | M12: Open tab
A13: 10 | B13: Food delivery — minority shareholdings | C13: EU + UK | D13: Material influence and minority shareholdings — on what basis did the CMA take jurisdiction over a c.16% stake, and how else have authorities treated minority shareholdings in merger control? | E13: =IF(LEN('Q10'!A16)>0,"Yes","No") | F13: =IF(COUNTA('Q10'!B21:B35)>0,"Yes","No") | G13: =IF('Q10'!B66="Yes","Completed",IF(COUNTA('Q10'!D39:D58)>0,"In review","Not started")) | H13: ='Q10'!B67 | I13: ='Q10'!D67 | J13: ='Q10'!B61 | K13: ='Q10'!B62 | L13: Q10 | M13: Open tab
A14: 11 | B14: Food delivery — evolution of practice | C14: EU + UK + ES | D14: The evolution of European food-delivery merger control, 2017–2025 — how has practice evolved from the first national marketplace consolidations to the recent Commission decisions? | E14: =IF(LEN('Q11'!A16)>0,"Yes","No") | F14: =IF(COUNTA('Q11'!B21:B35)>0,"Yes","No") | G14: =IF('Q11'!B66="Yes","Completed",IF(COUNTA('Q11'!D39:D58)>0,"In review","Not started")) | H14: ='Q11'!B67 | I14: ='Q11'!D67 | J14: ='Q11'!B61 | K14: ='Q11'!B62 | L14: Q11 | M14: Open tab
A15: 12 | B15: Dawn raids — legal professional privilege | C15: France | D15: At what stage is attorney-client privilege breached during a dawn raid — when the inspector reads the document, or only when it is later used? | E15: =IF(LEN('Q12'!A16)>0,"Yes","No") | F15: =IF(COUNTA('Q12'!B21:B35)>0,"Yes","No") | G15: =IF('Q12'!B66="Yes","Completed",IF(COUNTA('Q12'!D39:D58)>0,"In review","Not started")) | H15: ='Q12'!B67 | I15: ='Q12'!D67 | J15: ='Q12'!B61 | K15: ='Q12'!B62 | L15: Q12 | M15: Open tab
A16: 13 | B16: Dawn raids — personal data | C16: France | D16: Under what conditions must the Competition Authority protect personal data during a dawn raid? Does the GDPR apply? Must documents be sealed on request? | E16: =IF(LEN('Q13'!A16)>0,"Yes","No") | F16: =IF(COUNTA('Q13'!B21:B35)>0,"Yes","No") | G16: =IF('Q13'!B66="Yes","Completed",IF(COUNTA('Q13'!D39:D58)>0,"In review","Not started")) | H16: ='Q13'!B67 | I16: ='Q13'!D67 | J16: ='Q13'!B61 | K16: ='Q13'!B62 | L16: Q13 | M16: Open tab
A17: 14 | B17: Dawn raids — challenging a seizure | C17: France | D17: After a dawn raid, can the President of the Court of Appeal be seized in interim proceedings to urgently resolve attorney-client privilege disputes? On what legal basis and under what conditions? | E17: =IF(LEN('Q14'!A16)>0,"Yes","No") | F17: =IF(COUNTA('Q14'!B21:B35)>0,"Yes","No") | G17: =IF('Q14'!B66="Yes","Completed",IF(COUNTA('Q14'!D39:D58)>0,"In review","Not started")) | H17: ='Q14'!B67 | I17: ='Q14'!D67 | J17: ='Q14'!B61 | K17: ='Q14'!B62 | L17: Q14 | M17: Open tab
A18: 15 | B18: Dawn raids — legal professional privilege | C18: EU | D18: At what stage is attorney-client privilege breached during a European Commission inspection under Article 20 of Regulation 1/2003 — when the inspector reads the document, or only when the Commission later uses it? | E18: =IF(LEN('Q15'!A16)>0,"Yes","No") | F18: =IF(COUNTA('Q15'!B21:B35)>0,"Yes","No") | G18: =IF('Q15'!B66="Yes","Completed",IF(COUNTA('Q15'!D39:D58)>0,"In review","Not started")) | H18: ='Q15'!B67 | I18: ='Q15'!D67 | J18: ='Q15'!B61 | K18: ='Q15'!B62 | L18: Q15 | M18: Open tab
A19: 16 | B19: Dawn raids — personal data | C19: EU | D19: Under what conditions must the European Commission protect personal data during an inspection? Does the GDPR apply? Must documents be sealed on request? | E19: =IF(LEN('Q16'!A16)>0,"Yes","No") | F19: =IF(COUNTA('Q16'!B21:B35)>0,"Yes","No") | G19: =IF('Q16'!B66="Yes","Completed",IF(COUNTA('Q16'!D39:D58)>0,"In review","Not started")) | H19: ='Q16'!B67 | I19: ='Q16'!D67 | J19: ='Q16'!B61 | K19: ='Q16'!B62 | L19: Q16 | M19: Open tab
A20: 17 | B20: Dawn raids — challenging a seizure | C20: EU | D20: What procedural avenues exist to challenge seizure of privileged documents after a European Commission inspection? | E20: =IF(LEN('Q17'!A16)>0,"Yes","No") | F20: =IF(COUNTA('Q17'!B21:B35)>0,"Yes","No") | G20: =IF('Q17'!B66="Yes","Completed",IF(COUNTA('Q17'!D39:D58)>0,"In review","Not started")) | H20: ='Q17'!B67 | I20: ='Q17'!D67 | J20: ='Q17'!B61 | K20: ='Q17'!B62 | L20: Q17 | M20: Open tab
A21: 18 | B21: Dawn raids — legal professional privilege | C21: US | D21: At what stage is attorney-client privilege breached when US antitrust authorities gather documents — when the investigator reads the document, or only when it is later used? | E21: =IF(LEN('Q18'!A16)>0,"Yes","No") | F21: =IF(COUNTA('Q18'!B21:B35)>0,"Yes","No") | G21: =IF('Q18'!B66="Yes","Completed",IF(COUNTA('Q18'!D39:D58)>0,"In review","Not started")) | H21: ='Q18'!B67 | I21: ='Q18'!D67 | J21: ='Q18'!B61 | K21: ='Q18'!B62 | L21: Q18 | M21: Open tab
A22: 22 | B22: Food delivery — data access | C22: EU + UK | D22: Where a platform like Uber leverages data collected across its ecosystem to improve and strengthen its food delivery arm, how would such conduct be characterised under EU competition law — as tying/bundling, as an exploitative abuse, as leveraging into an adjacent market, or as a distinct data-driven theory of harm? Which category best fits, and what would be required to establish it under Article 102 TFEU? | E22: =IF(LEN('Q22'!A16)>0,"Yes","No") | F22: =IF(COUNTA('Q22'!B21:B35)>0,"Yes","No") | G22: =IF('Q22'!B66="Yes","Completed",IF(COUNTA('Q22'!D39:D58)>0,"In review","Not started")) | H22: ='Q22'!B67 | I22: ='Q22'!D67 | J22: ='Q22'!B61 | K22: ='Q22'!B62 | L22: Q22 | M22: Open tab
A23: 23 | B23: Food delivery — own fleet vs marketplace | C23: EU + UK + ES | D23: Can a food-delivery platform qualify as a provider of online intermediation services within the meaning of the P2B Regulation (EU) 2019/1150 — and if so, which obligations would it additionally have to comply with should it be designated as a gatekeeper under the DMA? | E23: =IF(LEN('Q23'!A16)>0,"Yes","No") | F23: =IF(COUNTA('Q23'!B21:B35)>0,"Yes","No") | G23: =IF('Q23'!B66="Yes","Completed",IF(COUNTA('Q23'!D39:D58)>0,"In review","Not started")) | H23: ='Q23'!B67 | I23: ='Q23'!D67 | J23: ='Q23'!B61 | K23: ='Q23'!B62 | L23: Q23 | M23: Open tab
A24: 24 | B24: Food delivery — which authority reviews | C24: EU + UK + ES | D24: Food-delivery transactions frequently fall below the EU Merger Regulation turnover thresholds yet raise cross-border concerns. In light of the CJEU's Illumina/Grail judgment restricting Article 22 upward referrals for deals that do not meet any national threshold, what mechanisms remain for the Commission to capture a below-threshold food-delivery 'killer acquisition'? | E24: =IF(LEN('Q24'!A16)>0,"Yes","No") | F24: =IF(COUNTA('Q24'!B21:B35)>0,"Yes","No") | G24: =IF('Q24'!B66="Yes","Completed",IF(COUNTA('Q24'!D39:D58)>0,"In review","Not started")) | H24: ='Q24'!B67 | I24: ='Q24'!D67 | J24: ='Q24'!B61 | K24: ='Q24'!B62 | L24: Q24 | M24: Open tab
A25: 25 | B25: Dawn raids — legal professional privilege | C25: EU | D25: Does legal professional privilege in EU competition law cover advice from a company's own in-house lawyers? How have the courts justified where the line falls, and what does that mean in practice during an inspection? | E25: =IF(LEN('Q25'!A16)>0,"Yes","No") | F25: =IF(COUNTA('Q25'!B21:B35)>0,"Yes","No") | G25: =IF('Q25'!B66="Yes","Completed",IF(COUNTA('Q25'!D39:D58)>0,"In review","Not started")) | H25: ='Q25'!B67 | I25: ='Q25'!D67 | J25: ='Q25'!B61 | K25: ='Q25'!B62 | L25: Q25 | M25: Open tab
A26: 26 | B26: Dawn raids — legal professional privilege | C26: France | D26: Where a French dawn raid seizes a mailbox or a set of files in bulk and privileged correspondence is found inside afterwards, what is the procedure for having it returned or destroyed, and who decides? | E26: =IF(LEN('Q26'!A16)>0,"Yes","No") | F26: =IF(COUNTA('Q26'!B21:B35)>0,"Yes","No") | G26: =IF('Q26'!B66="Yes","Completed",IF(COUNTA('Q26'!D39:D58)>0,"In review","Not started")) | H26: ='Q26'!B67 | I26: ='Q26'!D67 | J26: ='Q26'!B61 | K26: ='Q26'!B62 | L26: Q26 | M26: Open tab
A27: 27 | B27: Dawn raids — challenging a seizure | C27: France | D27: French law separates a challenge to the order authorising a dawn raid from a challenge to how the raid was carried out. What are the two routes, who hears each, what are the time limits, and what can each achieve? | E27: =IF(LEN('Q27'!A16)>0,"Yes","No") | F27: =IF(COUNTA('Q27'!B21:B35)>0,"Yes","No") | G27: =IF('Q27'!B66="Yes","Completed",IF(COUNTA('Q27'!D39:D58)>0,"In review","Not started")) | H27: ='Q27'!B67 | I27: ='Q27'!D67 | J27: ='Q27'!B61 | K27: ='Q27'!B62 | L27: Q27 | M27: Open tab
A28: 28 | B28: Dawn raids — the inspection decision | C28: EU | D28: What is the extent of the Commission's duty to state reasons under Article 20(4) of Regulation 1/2003 as regards the subject matter and purpose of an inspection decision and the identification of its addressees — and what are the consequences, in light of Nexans, Deutsche Bahn and Les Laboratoires Servier, where the scope of the inspection exceeds the reasonable grounds (indicia) actually in the Commission's possession? | E28: =IF(LEN('Q28'!A16)>0,"Yes","No") | F28: =IF(COUNTA('Q28'!B21:B35)>0,"Yes","No") | G28: =IF('Q28'!B66="Yes","Completed",IF(COUNTA('Q28'!D39:D58)>0,"In review","Not started")) | H28: ='Q28'!B67 | I28: ='Q28'!D67 | J28: ='Q28'!B61 | K28: ='Q28'!B62 | L28: Q28 | M28: Open tab
A29: 29 | B29: Dawn raids — the inspection decision | C29: EU | D29: Can an inspection decision be annulled in part where the Commission's evidence supports only some of the suspected infringement period it covers, and what then happens to material already gathered? | E29: =IF(LEN('Q29'!A16)>0,"Yes","No") | F29: =IF(COUNTA('Q29'!B21:B35)>0,"Yes","No") | G29: =IF('Q29'!B66="Yes","Completed",IF(COUNTA('Q29'!D39:D58)>0,"In review","Not started")) | H29: ='Q29'!B67 | I29: ='Q29'!D67 | J29: ='Q29'!B61 | K29: ='Q29'!B62 | L29: Q29 | M29: Open tab
A30: 30 | B30: Dawn raids — the inspection decision | C30: France | D30: How specific must a French dawn-raid authorisation be about the premises to be visited, the practices suspected, and the period covered? What has been held insufficient? | E30: =IF(LEN('Q30'!A16)>0,"Yes","No") | F30: =IF(COUNTA('Q30'!B21:B35)>0,"Yes","No") | G30: =IF('Q30'!B66="Yes","Completed",IF(COUNTA('Q30'!D39:D58)>0,"In review","Not started")) | H30: ='Q30'!B67 | I30: ='Q30'!D67 | J30: ='Q30'!B61 | K30: ='Q30'!B62 | L30: Q30 | M30: Open tab
A31: 34 | B31: Dawn raids — obstruction and seals | C31: EU | D31: Does the obstruction regime of Article 23(1) of Regulation 1/2003 — conceived for physical records and corporate email — still fit an environment of ephemeral, encrypted messaging on employees' personal devices? Where does the deletion of a WhatsApp or Signal message during or ahead of an inspection cross from ordinary personal housekeeping into a sanctionable procedural infringement, and how must intent and attribution be established when the device and the account belong to the individual rather than the undertaking? | E31: =IF(LEN('Q34'!A16)>0,"Yes","No") | F31: =IF(COUNTA('Q34'!B21:B35)>0,"Yes","No") | G31: =IF('Q34'!B66="Yes","Completed",IF(COUNTA('Q34'!D39:D58)>0,"In review","Not started")) | H31: ='Q34'!B67 | I31: ='Q34'!D67 | J31: ='Q34'!B61 | K31: ='Q34'!B62 | L31: Q34 | M31: Open tab
A32: 35 | B32: Dawn raids — obstruction and seals | C32: EU | D32: To what extent may an undertaking be fined for the breaking of a seal in the absence of any fault or intent, and how is that reconciled with the presumption of innocence? | E32: =IF(LEN('Q35'!A16)>0,"Yes","No") | F32: =IF(COUNTA('Q35'!B21:B35)>0,"Yes","No") | G32: =IF('Q35'!B66="Yes","Completed",IF(COUNTA('Q35'!D39:D58)>0,"In review","Not started")) | H32: ='Q35'!B67 | I32: ='Q35'!D67 | J32: ='Q35'!B61 | K32: ='Q35'!B62 | L32: Q35 | M32: Open tab
A33: 36 | B33: Dawn raids — obstruction and seals | C33: France | D33: What behavior during a French dawn raid (OVS) exposes a company to obstruction liability, and what training precautions follow from recent enforcement? | E33: =IF(LEN('Q36'!A16)>0,"Yes","No") | F33: =IF(COUNTA('Q36'!B21:B35)>0,"Yes","No") | G33: =IF('Q36'!B66="Yes","Completed",IF(COUNTA('Q36'!D39:D58)>0,"In review","Not started")) | H33: ='Q36'!B67 | I33: ='Q36'!D67 | J33: ='Q36'!B61 | K33: ='Q36'!B62 | L33: Q36 | M33: Open tab
A34: 38 | B34: Dawn raids — questioning staff | C34: EU | D34: To what extent may the Commission compel answers under Article 20(2)(e) of Regulation 1/2003 before the privilege against self-incrimination intervenes — and how the distinction between answering questions of fact and admitting an infringement remain workable in practice? | E34: =IF(LEN('Q38'!A16)>0,"Yes","No") | F34: =IF(COUNTA('Q38'!B21:B35)>0,"Yes","No") | G34: =IF('Q38'!B66="Yes","Completed",IF(COUNTA('Q38'!D39:D58)>0,"In review","Not started")) | H34: ='Q38'!B67 | I34: ='Q38'!D67 | J34: ='Q38'!B61 | K34: ='Q38'!B62 | L34: Q38 | M34: Open tab
A35: 39 | B35: Dawn raids — questioning staff | C35: France | D35: Can employees be required to answer questions during a French dawn raid, and what protection against self-incrimination do they and the company have? | E35: =IF(LEN('Q39'!A16)>0,"Yes","No") | F35: =IF(COUNTA('Q39'!B21:B35)>0,"Yes","No") | G35: =IF('Q39'!B66="Yes","Completed",IF(COUNTA('Q39'!D39:D58)>0,"In review","Not started")) | H35: ='Q39'!B67 | I35: ='Q39'!D67 | J35: ='Q39'!B61 | K35: ='Q39'!B62 | L35: Q39 | M35: Open tab
A36: 41 | B36: Dawn raids — electronic data | C36: EU | D36: May the Commission take a forensic copy of a company's electronic data and carry on examining it at its own premises after the inspection has ended? What safeguards apply, and what rights does the company keep over that copy? | E36: =IF(LEN('Q41'!A16)>0,"Yes","No") | F36: =IF(COUNTA('Q41'!B21:B35)>0,"Yes","No") | G36: =IF('Q41'!B66="Yes","Completed",IF(COUNTA('Q41'!D39:D58)>0,"In review","Not started")) | H36: ='Q41'!B67 | I36: ='Q41'!D67 | J36: ='Q41'!B61 | K36: ='Q41'!B62 | L36: Q41 | M36: Open tab
A37: 42 | B37: Dawn raids — electronic data | C37: EU | D37: Whose interests prevail when an inspection captures the private communications of employees who are not themselves under investigation — the Commission's investigative reach, or the privacy protected by Articles 7 and 8 of the Charter? And when does an undertaking's effort to shield that data become obstruction? | E37: =IF(LEN('Q42'!A16)>0,"Yes","No") | F37: =IF(COUNTA('Q42'!B21:B35)>0,"Yes","No") | G37: =IF('Q42'!B66="Yes","Completed",IF(COUNTA('Q42'!D39:D58)>0,"In review","Not started")) | H37: ='Q42'!B67 | I37: ='Q42'!D67 | J37: ='Q42'!B61 | K37: ='Q42'!B62 | L37: Q42 | M37: Open tab
A38: 43 | B38: Dawn raids — electronic data | C38: France | D38: Under what conditions can French competition authorities seize entire mailboxes during a dawn raid rather than sorting them on-site, how is the in-scope material subsequently identified, and what happens to material found to be out of scope? | E38: =IF(LEN('Q43'!A16)>0,"Yes","No") | F38: =IF(COUNTA('Q43'!B21:B35)>0,"Yes","No") | G38: =IF('Q43'!B66="Yes","Completed",IF(COUNTA('Q43'!D39:D58)>0,"In review","Not started")) | H38: ='Q43'!B67 | I38: ='Q43'!D67 | J38: ='Q43'!B61 | K38: ='Q43'!B62 | L38: Q43 | M38: Open tab
A39: 45 | B39: Dawn raids — evidence found by accident | C39: EU | D39: May the Commission use evidence of an infringement falling outside the subject matter of the inspection decision? What are the limits imposed by the relevant case law on the use of such incidental findings, and on what conditions may a chance discovery justify a new inspection? | E39: =IF(LEN('Q45'!A16)>0,"Yes","No") | F39: =IF(COUNTA('Q45'!B21:B35)>0,"Yes","No") | G39: =IF('Q45'!B66="Yes","Completed",IF(COUNTA('Q45'!D39:D58)>0,"In review","Not started")) | H39: ='Q45'!B67 | I39: ='Q45'!D67 | J39: ='Q45'!B61 | K39: ='Q45'!B62 | L39: Q45 | M39: Open tab
A40: 46 | B40: Dawn raids — evidence found by accident | C40: EU | D40: Can the Commission inspect a company over conduct a national authority has already investigated? What limits apply, and how have the courts treated the overlap? | E40: =IF(LEN('Q46'!A16)>0,"Yes","No") | F40: =IF(COUNTA('Q46'!B21:B35)>0,"Yes","No") | G40: =IF('Q46'!B66="Yes","Completed",IF(COUNTA('Q46'!D39:D58)>0,"In review","Not started")) | H40: ='Q46'!B67 | I40: ='Q46'!D67 | J40: ='Q46'!B61 | K40: ='Q46'!B62 | L40: Q46 | M40: Open tab
A41: 47 | B41: Dawn raids — premises and the courts | C41: EU | D41: How is the inviolability of business premises reconciled with the Commission's inspection powers under Article 20 of Regulation 1/2003 — in particular, when is prior judicial authorisation required, and what may the national court asked to authorise coercive assistance review under Article 20(8)? | E41: =IF(LEN('Q47'!A16)>0,"Yes","No") | F41: =IF(COUNTA('Q47'!B21:B35)>0,"Yes","No") | G41: =IF('Q47'!B66="Yes","Completed",IF(COUNTA('Q47'!D39:D58)>0,"In review","Not started")) | H41: ='Q47'!B67 | I41: ='Q47'!D67 | J41: ='Q47'!B61 | K41: ='Q47'!B62 | L41: Q47 | M41: Open tab
...

Sheet Scoring Summary
A1: Scoring Summary
A2: Team-facing summary. Experts only need to complete the question tabs; this sheet pulls verdicts together.
A4: Question ID | B4: Topic | C4: Total claims | D4: Supported | E4: Partly supported | F4: Not supported | G4: Wrong source | H4: Missing citation | I4: Not legal claim | J4: Final verdict | K4: Expert notes
A5: 1 | B5: Food delivery — market definition | C5: =COUNTA('Q01'!B39:B58) | D5: =COUNTIF('Q01'!D39:D58,"Supported") | E5: =COUNTIF('Q01'!D39:D58,"Partly supported") | F5: =COUNTIF('Q01'!D39:D58,"Not supported") | G5: =COUNTIF('Q01'!D39:D58,"Wrong source") | H5: =COUNTIF('Q01'!D39:D58,"Missing citation") | I5: =COUNTIF('Q01'!D39:D58,"Not a legal claim") | J5: ='Q01'!B61 | K5: ='Q01'!B62
A6: 2 | B6: Food delivery — multi-sided platforms | C6: =COUNTA('Q02'!B39:B58) | D6: =COUNTIF('Q02'!D39:D58,"Supported") | E6: =COUNTIF('Q02'!D39:D58,"Partly supported") | F6: =COUNTIF('Q02'!D39:D58,"Not supported") | G6: =COUNTIF('Q02'!D39:D58,"Wrong source") | H6: =COUNTIF('Q02'!D39:D58,"Missing citation") | I6: =COUNTIF('Q02'!D39:D58,"Not a legal claim") | J6: ='Q02'!B61 | K6: ='Q02'!B62
A7: 3 | B7: Food delivery — market boundary | C7: =COUNTA('Q03'!B39:B58) | D7: =COUNTIF('Q03'!D39:D58,"Supported") | E7: =COUNTIF('Q03'!D39:D58,"Partly supported") | F7: =COUNTIF('Q03'!D39:D58,"Not supported") | G7: =COUNTIF('Q03'!D39:D58,"Wrong source") | H7: =COUNTIF('Q03'!D39:D58,"Missing citation") | I7: =COUNTIF('Q03'!D39:D58,"Not a legal claim") | J7: ='Q03'!B61 | K7: ='Q03'!B62
A8: 4 | B8: Food delivery — failing-firm defence | C8: =COUNTA('Q04'!B39:B58) | D8: =COUNTIF('Q04'!D39:D58,"Supported") | E8: =COUNTIF('Q04'!D39:D58,"Partly supported") | F8: =COUNTIF('Q04'!D39:D58,"Not supported") | G8: =COUNTIF('Q04'!D39:D58,"Wrong source") | H8: =COUNTIF('Q04'!D39:D58,"Missing citation") | I8: =COUNTIF('Q04'!D39:D58,"Not a legal claim") | J8: ='Q04'!B61 | K8: ='Q04'!B62
A9: 5 | B9: Food delivery — COVID-19 | C9: =COUNTA('Q05'!B39:B58) | D9: =COUNTIF('Q05'!D39:D58,"Supported") | E9: =COUNTIF('Q05'!D39:D58,"Partly supported") | F9: =COUNTIF('Q05'!D39:D58,"Not supported") | G9: =COUNTIF('Q05'!D39:D58,"Wrong source") | H9: =COUNTIF('Q05'!D39:D58,"Missing citation") | I9: =COUNTIF('Q05'!D39:D58,"Not a legal claim") | J9: ='Q05'!B61 | K9: ='Q05'!B62
A10: 6 | B10: Food delivery — potential competition | C10: =COUNTA('Q06'!B39:B58) | D10: =COUNTIF('Q06'!D39:D58,"Supported") | E10: =COUNTIF('Q06'!D39:D58,"Partly supported") | F10: =COUNTIF('Q06'!D39:D58,"Not supported") | G10: =COUNTIF('Q06'!D39:D58,"Wrong source") | H10: =COUNTIF('Q06'!D39:D58,"Missing citation") | I10: =COUNTIF('Q06'!D39:D58,"Not a legal claim") | J10: ='Q06'!B61 | K10: ='Q06'!B62
A11: 7 | B11: Food delivery — no-poach agreements | C11: =COUNTA('Q07'!B39:B58) | D11: =COUNTIF('Q07'!D39:D58,"Supported") | E11: =COUNTIF('Q07'!D39:D58,"Partly supported") | F11: =COUNTIF('Q07'!D39:D58,"Not supported") | G11: =COUNTIF('Q07'!D39:D58,"Wrong source") | H11: =COUNTIF('Q07'!D39:D58,"Missing citation") | I11: =COUNTIF('Q07'!D39:D58,"Not a legal claim") | J11: ='Q07'!B61 | K11: ='Q07'!B62
A12: 8 | B12: Food delivery — remedies | C12: =COUNTA('Q08'!B39:B58) | D12: =COUNTIF('Q08'!D39:D58,"Supported") | E12: =COUNTIF('Q08'!D39:D58,"Partly supported") | F12: =COUNTIF('Q08'!D39:D58,"Not supported") | G12: =COUNTIF('Q08'!D39:D58,"Wrong source") | H12: =COUNTIF('Q08'!D39:D58,"Missing citation") | I12: =COUNTIF('Q08'!D39:D58,"Not a legal claim") | J12: ='Q08'!B61 | K12: ='Q08'!B62
A13: 9 | B13: Food delivery — Spanish practice | C13: =COUNTA('Q09'!B39:B58) | D13: =COUNTIF('Q09'!D39:D58,"Supported") | E13: =COUNTIF('Q09'!D39:D58,"Partly supported") | F13: =COUNTIF('Q09'!D39:D58,"Not supported") | G13: =COUNTIF('Q09'!D39:D58,"Wrong source") | H13: =COUNTIF('Q09'!D39:D58,"Missing citation") | I13: =COUNTIF('Q09'!D39:D58,"Not a legal claim") | J13: ='Q09'!B61 | K13: ='Q09'!B62
A14: 10 | B14: Food delivery — minority shareholdings | C14: =COUNTA('Q10'!B39:B58) | D14: =COUNTIF('Q10'!D39:D58,"Supported") | E14: =COUNTIF('Q10'!D39:D58,"Partly supported") | F14: =COUNTIF('Q10'!D39:D58,"Not supported") | G14: =COUNTIF('Q10'!D39:D58,"Wrong source") | H14: =COUNTIF('Q10'!D39:D58,"Missing citation") | I14: =COUNTIF('Q10'!D39:D58,"Not a legal claim") | J14: ='Q10'!B61 | K14: ='Q10'!B62
A15: 11 | B15: Food delivery — evolution of practice | C15: =COUNTA('Q11'!B39:B58) | D15: =COUNTIF('Q11'!D39:D58,"Supported") | E15: =COUNTIF('Q11'!D39:D58,"Partly supported") | F15: =COUNTIF('Q11'!D39:D58,"Not supported") | G15: =COUNTIF('Q11'!D39:D58,"Wrong source") | H15: =COUNTIF('Q11'!D39:D58,"Missing citation") | I15: =COUNTIF('Q11'!D39:D58,"Not a legal claim") | J15: ='Q11'!B61 | K15: ='Q11'!B62
A16: 12 | B16: Dawn raids — legal professional privilege | C16: =COUNTA('Q12'!B39:B58) | D16: =COUNTIF('Q12'!D39:D58,"Supported") | E16: =COUNTIF('Q12'!D39:D58,"Partly supported") | F16: =COUNTIF('Q12'!D39:D58,"Not supported") | G16: =COUNTIF('Q12'!D39:D58,"Wrong source") | H16: =COUNTIF('Q12'!D39:D58,"Missing citation") | I16: =COUNTIF('Q12'!D39:D58,"Not a legal claim") | J16: ='Q12'!B61 | K16: ='Q12'!B62
A17: 13 | B17: Dawn raids — personal data | C17: =COUNTA('Q13'!B39:B58) | D17: =COUNTIF('Q13'!D39:D58,"Supported") | E17: =COUNTIF('Q13'!D39:D58,"Partly supported") | F17: =COUNTIF('Q13'!D39:D58,"Not supported") | G17: =COUNTIF('Q13'!D39:D58,"Wrong source") | H17: =COUNTIF('Q13'!D39:D58,"Missing citation") | I17: =COUNTIF('Q13'!D39:D58,"Not a legal claim") | J17: ='Q13'!B61 | K17: ='Q13'!B62
A18: 14 | B18: Dawn raids — challenging a seizure | C18: =COUNTA('Q14'!B39:B58) | D18: =COUNTIF('Q14'!D39:D58,"Supported") | E18: =COUNTIF('Q14'!D39:D58,"Partly supported") | F18: =COUNTIF('Q14'!D39:D58,"Not supported") | G18: =COUNTIF('Q14'!D39:D58,"Wrong source") | H18: =COUNTIF('Q14'!D39:D58,"Missing citation") | I18: =COUNTIF('Q14'!D39:D58,"Not a legal claim") | J18: ='Q14'!B61 | K18: ='Q14'!B62
A19: 15 | B19: Dawn raids — legal professional privilege | C19: =COUNTA('Q15'!B39:B58) | D19: =COUNTIF('Q15'!D39:D58,"Supported") | E19: =COUNTIF('Q15'!D39:D58,"Partly supported") | F19: =COUNTIF('Q15'!D39:D58,"Not supported") | G19: =COUNTIF('Q15'!D39:D58,"Wrong source") | H19: =COUNTIF('Q15'!D39:D58,"Missing citation") | I19: =COUNTIF('Q15'!D39:D58,"Not a legal claim") | J19: ='Q15'!B61 | K19: ='Q15'!B62
A20: 16 | B20: Dawn raids — personal data | C20: =COUNTA('Q16'!B39:B58) | D20: =COUNTIF('Q16'!D39:D58,"Supported") | E20: =COUNTIF('Q16'!D39:D58,"Partly supported") | F20: =COUNTIF('Q16'!D39:D58,"Not supported") | G20: =COUNTIF('Q16'!D39:D58,"Wrong source") | H20: =COUNTIF('Q16'!D39:D58,"Missing citation") | I20: =COUNTIF('Q16'!D39:D58,"Not a legal claim") | J20: ='Q16'!B61 | K20: ='Q16'!B62
A21: 17 | B21: Dawn raids — challenging a seizure | C21: =COUNTA('Q17'!B39:B58) | D21: =COUNTIF('Q17'!D39:D58,"Supported") | E21: =COUNTIF('Q17'!D39:D58,"Partly supported") | F21: =COUNTIF('Q17'!D39:D58,"Not supported") | G21: =COUNTIF('Q17'!D39:D58,"Wrong source") | H21: =COUNTIF('Q17'!D39:D58,"Missing citation") | I21: =COUNTIF('Q17'!D39:D58,"Not a legal claim") | J21: ='Q17'!B61 | K21: ='Q17'!B62
A22: 18 | B22: Dawn raids — legal professional privilege | C22: =COUNTA('Q18'!B39:B58) | D22: =COUNTIF('Q18'!D39:D58,"Supported") | E22: =COUNTIF('Q18'!D39:D58,"Partly supported") | F22: =COUNTIF('Q18'!D39:D58,"Not supported") | G22: =COUNTIF('Q18'!D39:D58,"Wrong source") | H22: =COUNTIF('Q18'!D39:D58,"Missing citation") | I22: =COUNTIF('Q18'!D39:D58,"Not a legal claim") | J22: ='Q18'!B61 | K22: ='Q18'!B62
A23: 22 | B23: Food delivery — data access | C23: =COUNTA('Q22'!B39:B58) | D23: =COUNTIF('Q22'!D39:D58,"Supported") | E23: =COUNTIF('Q22'!D39:D58,"Partly supported") | F23: =COUNTIF('Q22'!D39:D58,"Not supported") | G23: =COUNTIF('Q22'!D39:D58,"Wrong source") | H23: =COUNTIF('Q22'!D39:D58,"Missing citation") | I23: =COUNTIF('Q22'!D39:D58,"Not a legal claim") | J23: ='Q22'!B61 | K23: ='Q22'!B62
A24: 23 | B24: Food delivery — own fleet vs marketplace | C24: =COUNTA('Q23'!B39:B58) | D24: =COUNTIF('Q23'!D39:D58,"Supported") | E24: =COUNTIF('Q23'!D39:D58,"Partly supported") | F24: =COUNTIF('Q23'!D39:D58,"Not supported") | G24: =COUNTIF('Q23'!D39:D58,"Wrong source") | H24: =COUNTIF('Q23'!D39:D58,"Missing citation") | I24: =COUNTIF('Q23'!D39:D58,"Not a legal claim") | J24: ='Q23'!B61 | K24: ='Q23'!B62
A25: 24 | B25: Food delivery — which authority reviews | C25: =COUNTA('Q24'!B39:B58) | D25: =COUNTIF('Q24'!D39:D58,"Supported") | E25: =COUNTIF('Q24'!D39:D58,"Partly supported") | F25: =COUNTIF('Q24'!D39:D58,"Not supported") | G25: =COUNTIF('Q24'!D39:D58,"Wrong source") | H25: =COUNTIF('Q24'!D39:D58,"Missing citation") | I25: =COUNTIF('Q24'!D39:D58,"Not a legal claim") | J25: ='Q24'!B61 | K25: ='Q24'!B62
A26: 25 | B26: Dawn raids — legal professional privilege | C26: =COUNTA('Q25'!B39:B58) | D26: =COUNTIF('Q25'!D39:D58,"Supported") | E26: =COUNTIF('Q25'!D39:D58,"Partly supported") | F26: =COUNTIF('Q25'!D39:D58,"Not supported") | G26: =COUNTIF('Q25'!D39:D58,"Wrong source") | H26: =COUNTIF('Q25'!D39:D58,"Missing citation") | I26: =COUNTIF('Q25'!D39:D58,"Not a legal claim") | J26: ='Q25'!B61 | K26: ='Q25'!B62
A27: 26 | B27: Dawn raids — legal professional privilege | C27: =COUNTA('Q26'!B39:B58) | D27: =COUNTIF('Q26'!D39:D58,"Supported") | E27: =COUNTIF('Q26'!D39:D58,"Partly supported") | F27: =COUNTIF('Q26'!D39:D58,"Not supported") | G27: =COUNTIF('Q26'!D39:D58,"Wrong source") | H27: =COUNTIF('Q26'!D39:D58,"Missing citation") | I27: =COUNTIF('Q26'!D39:D58,"Not a legal claim") | J27: ='Q26'!B61 | K27: ='Q26'!B62
A28: 27 | B28: Dawn raids — challenging a seizure | C28: =COUNTA('Q27'!B39:B58) | D28: =COUNTIF('Q27'!D39:D58,"Supported") | E28: =COUNTIF('Q27'!D39:D58,"Partly supported") | F28: =COUNTIF('Q27'!D39:D58,"Not supported") | G28: =COUNTIF('Q27'!D39:D58,"Wrong source") | H28: =COUNTIF('Q27'!D39:D58,"Missing citation") | I28: =COUNTIF('Q27'!D39:D58,"Not a legal claim") | J28: ='Q27'!B61 | K28: ='Q27'!B62
A29: 28 | B29: Dawn raids — the inspection decision | C29: =COUNTA('Q28'!B39:B58) | D29: =COUNTIF('Q28'!D39:D58,"Supported") | E29: =COUNTIF('Q28'!D39:D58,"Partly supported") | F29: =COUNTIF('Q28'!D39:D58,"Not supported") | G29: =COUNTIF('Q28'!D39:D58,"Wrong source") | H29: =COUNTIF('Q28'!D39:D58,"Missing citation") | I29: =COUNTIF('Q28'!D39:D58,"Not a legal claim") | J29: ='Q28'!B61 | K29: ='Q28'!B62
A30: 29 | B30: Dawn raids — the inspection decision | C30: =COUNTA('Q29'!B39:B58) | D30: =COUNTIF('Q29'!D39:D58,"Supported") | E30: =COUNTIF('Q29'!D39:D58,"Partly supported") | F30: =COUNTIF('Q29'!D39:D58,"Not supported") | G30: =COUNTIF('Q29'!D39:D58,"Wrong source") | H30: =COUNTIF('Q29'!D39:D58,"Missing citation") | I30: =COUNTIF('Q29'!D39:D58,"Not a legal claim") | J30: ='Q29'!B61 | K30: ='Q29'!B62
A31: 30 | B31: Dawn raids — the inspection decision | C31: =COUNTA('Q30'!B39:B58) | D31: =COUNTIF('Q30'!D39:D58,"Supported") | E31: =COUNTIF('Q30'!D39:D58,"Partly supported") | F31: =COUNTIF('Q30'!D39:D58,"Not supported") | G31: =COUNTIF('Q30'!D39:D58,"Wrong source") | H31: =COUNTIF('Q30'!D39:D58,"Missing citation") | I31: =COUNTIF('Q30'!D39:D58,"Not a legal claim") | J31: ='Q30'!B61 | K31: ='Q30'!B62
A32: 34 | B32: Dawn raids — obstruction and seals | C32: =COUNTA('Q34'!B39:B58) | D32: =COUNTIF('Q34'!D39:D58,"Supported") | E32: =COUNTIF('Q34'!D39:D58,"Partly supported") | F32: =COUNTIF('Q34'!D39:D58,"Not supported") | G32: =COUNTIF('Q34'!D39:D58,"Wrong source") | H32: =COUNTIF('Q34'!D39:D58,"Missing citation") | I32: =COUNTIF('Q34'!D39:D58,"Not a legal claim") | J32: ='Q34'!B61 | K32: ='Q34'!B62
A33: 35 | B33: Dawn raids — obstruction and seals | C33: =COUNTA('Q35'!B39:B58) | D33: =COUNTIF('Q35'!D39:D58,"Supported") | E33: =COUNTIF('Q35'!D39:D58,"Partly supported") | F33: =COUNTIF('Q35'!D39:D58,"Not supported") | G33: =COUNTIF('Q35'!D39:D58,"Wrong source") | H33: =COUNTIF('Q35'!D39:D58,"Missing citation") | I33: =COUNTIF('Q35'!D39:D58,"Not a legal claim") | J33: ='Q35'!B61 | K33: ='Q35'!B62
A34: 36 | B34: Dawn raids — obstruction and seals | C34: =COUNTA('Q36'!B39:B58) | D34: =COUNTIF('Q36'!D39:D58,"Supported") | E34: =COUNTIF('Q36'!D39:D58,"Partly supported") | F34: =COUNTIF('Q36'!D39:D58,"Not supported") | G34: =COUNTIF('Q36'!D39:D58,"Wrong source") | H34: =COUNTIF('Q36'!D39:D58,"Missing citation") | I34: =COUNTIF('Q36'!D39:D58,"Not a legal claim") | J34: ='Q36'!B61 | K34: ='Q36'!B62
A35: 38 | B35: Dawn raids — questioning staff | C35: =COUNTA('Q38'!B39:B58) | D35: =COUNTIF('Q38'!D39:D58,"Supported") | E35: =COUNTIF('Q38'!D39:D58,"Partly supported") | F35: =COUNTIF('Q38'!D39:D58,"Not supported") | G35: =COUNTIF('Q38'!D39:D58,"Wrong source") | H35: =COUNTIF('Q38'!D39:D58,"Missing citation") | I35: =COUNTIF('Q38'!D39:D58,"Not a legal claim") | J35: ='Q38'!B61 | K35: ='Q38'!B62
A36: 39 | B36: Dawn raids — questioning staff | C36: =COUNTA('Q39'!B39:B58) | D36: =COUNTIF('Q39'!D39:D58,"Supported") | E36: =COUNTIF('Q39'!D39:D58,"Partly supported") | F36: =COUNTIF('Q39'!D39:D58,"Not supported") | G36: =COUNTIF('Q39'!D39:D58,"Wrong source") | H36: =COUNTIF('Q39'!D39:D58,"Missing citation") | I36: =COUNTIF('Q39'!D39:D58,"Not a legal claim") | J36: ='Q39'!B61 | K36: ='Q39'!B62
A37: 41 | B37: Dawn raids — electronic data | C37: =COUNTA('Q41'!B39:B58) | D37: =COUNTIF('Q41'!D39:D58,"Supported") | E37: =COUNTIF('Q41'!D39:D58,"Partly supported") | F37: =COUNTIF('Q41'!D39:D58,"Not supported") | G37: =COUNTIF('Q41'!D39:D58,"Wrong source") | H37: =COUNTIF('Q41'!D39:D58,"Missing citation") | I37: =COUNTIF('Q41'!D39:D58,"Not a legal claim") | J37: ='Q41'!B61 | K37: ='Q41'!B62
A38: 42 | B38: Dawn raids — electronic data | C38: =COUNTA('Q42'!B39:B58) | D38: =COUNTIF('Q42'!D39:D58,"Supported") | E38: =COUNTIF('Q42'!D39:D58,"Partly supported") | F38: =COUNTIF('Q42'!D39:D58,"Not supported") | G38: =COUNTIF('Q42'!D39:D58,"Wrong source") | H38: =COUNTIF('Q42'!D39:D58,"Missing citation") | I38: =COUNTIF('Q42'!D39:D58,"Not a legal claim") | J38: ='Q42'!B61 | K38: ='Q42'!B62
A39: 43 | B39: Dawn raids — electronic data | C39: =COUNTA('Q43'!B39:B58) | D39: =COUNTIF('Q43'!D39:D58,"Supported") | E39: =COUNTIF('Q43'!D39:D58,"Partly supported") | F39: =COUNTIF('Q43'!D39:D58,"Not supported") | G39: =COUNTIF('Q43'!D39:D58,"Wrong source") | H39: =COUNTIF('Q43'!D39:D58,"Missing citation") | I39: =COUNTIF('Q43'!D39:D58,"Not a legal claim") | J39: ='Q43'!B61 | K39: ='Q43'!B62
A40: 45 | B40: Dawn raids — evidence found by accident | C40: =COUNTA('Q45'!B39:B58) | D40: =COUNTIF('Q45'!D39:D58,"Supported") | E40: =COUNTIF('Q45'!D39:D58,"Partly supported") | F40: =COUNTIF('Q45'!D39:D58,"Not supported") | G40: =COUNTIF('Q45'!D39:D58,"Wrong source") | H40: =COUNTIF('Q45'!D39:D58,"Missing citation") | I40: =COUNTIF('Q45'!D39:D58,"Not a legal claim") | J40: ='Q45'!B61 | K40: ='Q45'!B62
A41: 46 | B41: Dawn raids — evidence found by accident | C41: =COUNTA('Q46'!B39:B58) | D41: =COUNTIF('Q46'!D39:D58,"Supported") | E41: =COUNTIF('Q46'!D39:D58,"Partly supported") | F41: =COUNTIF('Q46'!D39:D58,"Not supported") | G41: =COUNTIF('Q46'!D39:D58,"Wrong source") | H41: =COUNTIF('Q46'!D39:D58,"Missing citation") | I41: =COUNTIF('Q46'!D39:D58,"Not a legal claim") | J41: ='Q46'!B61 | K41: ='Q46'!B62
...

Sheet Q01
A1: Q01 — Expert Review | I1: Back to status
A3: Question metadata
A4: Question ID | B4: 1
A5: Topic | B5: Food delivery — market definition
A6: Scope | B6: EU + UK + ES
A7: Original reviewer | B7: Carolina
A8: Original status | B8: Approved
A10: Question | B10: The relevant market in a food-delivery acquisition — how have the Commission and national authorities defined the relevant product and geographic markets, and on what rationales?
A14: Generated answer
A15: Paste the generated answer below.
A19: Run ID | C19: Run date | E19: Model / prompt version | G19: Corpus snapshot
A20: Retrieval set review
A21: Rank | B21: Retrieved source | C21: Source type | D21: Jurisdiction | E21: URL / Document ID | F21: Returned by engine? | G21: Required source? | H21: Trap? | I21: Expert verdict | J21: Notes
A22: 1
A23: 2
A24: 3
A25: 4
A26: 5
A27: 6
A28: 7
A29: 8
A30: 9
A31: 10
A32: 11
A33: 12
... A36: 15
A38: Claim-by-claim review
A39: Claim ID | B39: Claim from answer | C39: Citation used | D39: Expert verdict | E39: Issue type | F39: Cited passage / source note | G39: Required fix / comment | H39: Reviewer
A40: 1
A41: 2
A42: 3
A43: 4
A44: 5
A45: 6
A46: 7
A47: 8
A48: 9
A49: 10
A50: 11
A51: 12
...

Sheet Q02
A1: Q02 — Expert Review | I1: Back to status
A3: Question metadata
A4: Question ID | B4: 2
A5: Topic | B5: Food delivery — multi-sided platforms
A6: Scope | B6: EU + UK + ES
A7: Original reviewer | B7: Carolina
A8: Original status | B8: Approved
A10: Question | B10: Food delivery as a multi-sided platform — have authorities analysed these platforms as two- or multi-sided markets, and which sides actually entered the analysis?
A14: Generated answer
A15: Paste the generated answer below.
A19: Run ID | C19: Run date | E19: Model / prompt version | G19: Corpus snapshot
A20: Retrieval set review
A21: Rank | B21: Retrieved source | C21: Source type | D21: Jurisdiction | E21: URL / Document ID | F21: Returned by engine? | G21: Required source? | H21: Trap? | I21: Expert verdict | J21: Notes
A22: 1
A23: 2
A24: 3
A25: 4
A26: 5
A27: 6
A28: 7
A29: 8
A30: 9
A31: 10
A32: 11
A33: 12
... A36: 15
A38: Claim-by-claim review
A39: Claim ID | B39: Claim from answer | C39: Citation used | D39: Expert verdict | E39: Issue type | F39: Cited passage / source note | G39: Required fix / comment | H39: Reviewer
A40: 1
A41: 2
A42: 3
A43: 4
A44: 5
A45: 6
A46: 7
A47: 8
A48: 9
A49: 10
A50: 11
A51: 12
...

Sheet Q03
A1: Q03 — Expert Review | I1: Back to status
A3: Question metadata
A4: Question ID | B4: 3
A5: Topic | B5: Food delivery — market boundary
A6: Scope | B6: UK (ES colour)
A7: Original reviewer | B7: Carolina
A8: Original status | B8: Approved
A10: Question | B10: Grocery, quick commerce, and the market boundary — separate markets from restaurant meal delivery, or one broad on-demand delivery market?
A14: Generated answer
A15: Paste the generated answer below.
A19: Run ID | C19: Run date | E19: Model / prompt version | G19: Corpus snapshot
A20: Retrieval set review
A21: Rank | B21: Retrieved source | C21: Source type | D21: Jurisdiction | E21: URL / Document ID | F21: Returned by engine? | G21: Required source? | H21: Trap? | I21: Expert verdict | J21: Notes
A22: 1
A23: 2
A24: 3
A25: 4
A26: 5
A27: 6
A28: 7
A29: 8
A30: 9
A31: 10
A32: 11
A33: 12
... A36: 15
A38: Claim-by-claim review
A39: Claim ID | B39: Claim from answer | C39: Citation used | D39: Expert verdict | E39: Issue type | F39: Cited passage / source note | G39: Required fix / comment | H39: Reviewer
A40: 1
A41: 2
A42: 3
A43: 4
A44: 5
A45: 6
A46: 7
A47: 8
A48: 9
A49: 10
A50: 11
A51: 12
...

Sheet Q04
A1: Q04 — Expert Review | I1: Back to status
A3: Question metadata
A4: Question ID | B4: 4
A5: Topic | B5: Food delivery — failing-firm defence
A6: Scope | B6: UK
A7: Original reviewer | B7: Carolina
A8: Original status | B8: Approved
A10: Question | B10: The failing-firm defence in food delivery — has an exiting-firm counterfactual ever been accepted, did it survive to the final decision, and on what evidence?
A14: Generated answer
A15: Paste the generated answer below.
A19: Run ID | C19: Run date | E19: Model / prompt version | G19: Corpus snapshot
A20: Retrieval set review
A21: Rank | B21: Retrieved source | C21: Source type | D21: Jurisdiction | E21: URL / Document ID | F21: Returned by engine? | G21: Required source? | H21: Trap? | I21: Expert verdict | J21: Notes
A22: 1
A23: 2
A24: 3
A25: 4
A26: 5
A27: 6
A28: 7
A29: 8
A30: 9
A31: 10
A32: 11
A33: 12
... A36: 15
A38: Claim-by-claim review
A39: Claim ID | B39: Claim from answer | C39: Citation used | D39: Expert verdict | E39: Issue type | F39: Cited passage / source note | G39: Required fix / comment | H39: Reviewer
A40: 1
A41: 2
A42: 3
A43: 4
A44: 5
A45: 6
A46: 7
A47: 8
A48: 9
A49: 10
A50: 11
A51: 12
...

Sheet Q05
A1: Q05 — Expert Review | I1: Back to status
A3: Question metadata
A4: Question ID | B4: 5
A5: Topic | B5: Food delivery — COVID-19
A6: Scope | B6: UK
A7: Original reviewer | B7: Carolina
A8: Original status | B8: Approved
A10: Question | B10: COVID-19 in the competitive assessment — how did the pandemic actually enter the analysis: counterfactual, market definition, or not at all?
A14: Generated answer
A15: Paste the generated answer below.
A19: Run ID | C19: Run date | E19: Model / prompt version | G19: Corpus snapshot
A20: Retrieval set review
A21: Rank | B21: Retrieved source | C21: Source type | D21: Jurisdiction | E21: URL / Document ID | F21: Returned by engine? | G21: Required source? | H21: Trap? | I21: Expert verdict | J21: Notes
A22: 1
A23: 2
A24: 3
A25: 4
A26: 5
A27: 6
A28: 7
A29: 8
A30: 9
A31: 10
A32: 11
A33: 12
... A36: 15
A38: Claim-by-claim review
A39: Claim ID | B39: Claim from answer | C39: Citation used | D39: Expert verdict | E39: Issue type | F39: Cited passage / source note | G39: Required fix / comment | H39: Reviewer
A40: 1
A41: 2
A42: 3
A43: 4
A44: 5
A45: 6
A46: 7
A47: 8
A48: 9
A49: 10
A50: 11
A51: 12
...

Sheet Q06
A1: Q06 — Expert Review | I1: Back to status
A3: Question metadata
A4: Question ID | B4: 6
A5: Topic | B5: Food delivery — potential competition
A6: Scope | B6: UK
A7: Original reviewer | B7: Carolina
A8: Original status | B8: Approved
A10: Question | B10: Potential competition and re-entry — where the acquirer is not active in the UK, how has the CMA treated entry or re-entry absent the merger?
A14: Generated answer
A15: Paste the generated answer below.
A19: Run ID | C19: Run date | E19: Model / prompt version | G19: Corpus snapshot
A20: Retrieval set review
A21: Rank | B21: Retrieved source | C21: Source type | D21: Jurisdiction | E21: URL / Document ID | F21: Returned by engine? | G21: Required source? | H21: Trap? | I21: Expert verdict | J21: Notes
A22: 1
A23: 2
A24: 3
A25: 4
A26: 5
A27: 6
A28: 7
A29: 8
A30: 9
A31: 10
A32: 11
A33: 12
... A36: 15
A38: Claim-by-claim review
A39: Claim ID | B39: Claim from answer | C39: Citation used | D39: Expert verdict | E39: Issue type | F39: Cited passage / source note | G39: Required fix / comment | H39: Reviewer
A40: 1
A41: 2
A42: 3
A43: 4
A44: 5
A45: 6
A46: 7
A47: 8
A48: 9
A49: 10
A50: 11
A51: 12
...

Sheet Q07
A1: Q07 — Expert Review | I1: Back to status
A3: Question metadata
A4: Question ID | B4: 7
A5: Topic | B5: Food delivery — no-poach agreements
A6: Scope | B6: EU
A7: Original reviewer | B7: Carolina
A8: Original status | B8: Approved
A10: Question | B10: No-poach agreements under Article 101 — can a reciprocal agreement not to hire each other's staff infringe Article 101, and what is the leading precedent and fine?
A14: Generated answer
A15: Paste the generated answer below.
A19: Run ID | C19: Run date | E19: Model / prompt version | G19: Corpus snapshot
A20: Retrieval set review
A21: Rank | B21: Retrieved source | C21: Source type | D21: Jurisdiction | E21: URL / Document ID | F21: Returned by engine? | G21: Required source? | H21: Trap? | I21: Expert verdict | J21: Notes
A22: 1
A23: 2
A24: 3
A25: 4
A26: 5
A27: 6
A28: 7
A29: 8
A30: 9
A31: 10
A32: 11
A33: 12
... A36: 15
A38: Claim-by-claim review
A39: Claim ID | B39: Claim from answer | C39: Citation used | D39: Expert verdict | E39: Issue type | F39: Cited passage / source note | G39: Required fix / comment | H39: Reviewer
A40: 1
A41: 2
A42: 3
A43: 4
A44: 5
A45: 6
A46: 7
A47: 8
A48: 9
A49: 10
A50: 11
A51: 12
...

Sheet Q08
A1: Q08 — Expert Review | I1: Back to status
A3: Question metadata
A4: Question ID | B4: 8
A5: Topic | B5: Food delivery — remedies
A6: Scope | B6: EU + UK + ES
A7: Original reviewer | B7: Carolina
A8: Original status | B8: Approved
A10: Question | B10: Remedies in food-delivery mergers — which European reviews ended in remedies or commitments, and what did they look like?
A14: Generated answer
A15: Paste the generated answer below.
A19: Run ID | C19: Run date | E19: Model / prompt version | G19: Corpus snapshot
A20: Retrieval set review
A21: Rank | B21: Retrieved source | C21: Source type | D21: Jurisdiction | E21: URL / Document ID | F21: Returned by engine? | G21: Required source? | H21: Trap? | I21: Expert verdict | J21: Notes
A22: 1
A23: 2
A24: 3
A25: 4
A26: 5
A27: 6
A28: 7
A29: 8
A30: 9
A31: 10
A32: 11
A33: 12
... A36: 15
A38: Claim-by-claim review
A39: Claim ID | B39: Claim from answer | C39: Citation used | D39: Expert verdict | E39: Issue type | F39: Cited passage / source note | G39: Required fix / comment | H39: Reviewer
A40: 1
A41: 2
A42: 3
A43: 4
A44: 5
A45: 6
A46: 7
A47: 8
A48: 9
A49: 10
A50: 11
A51: 12
...

Sheet Q09
A1: Q09 — Expert Review | I1: Back to status
A3: Question metadata
A4: Question ID | B4: 9
A5: Topic | B5: Food delivery — Spanish practice
A6: Scope | B6: ES
A7: Original reviewer | B7: Carolina
A8: Original status | B8: Approved
A10: Question | B10: The Spanish (CNMC) food-delivery reviews — what is the CNMC's decisional practice, how many cases, and how were they resolved?
A14: Generated answer
A15: Paste the generated answer below.
A19: Run ID | C19: Run date | E19: Model / prompt version | G19: Corpus snapshot
A20: Retrieval set review
A21: Rank | B21: Retrieved source | C21: Source type | D21: Jurisdiction | E21: URL / Document ID | F21: Returned by engine? | G21: Required source? | H21: Trap? | I21: Expert verdict | J21: Notes
A22: 1
A23: 2
A24: 3
A25: 4
A26: 5
A27: 6
A28: 7
A29: 8
A30: 9
A31: 10
A32: 11
A33: 12
... A36: 15
A38: Claim-by-claim review
A39: Claim ID | B39: Claim from answer | C39: Citation used | D39: Expert verdict | E39: Issue type | F39: Cited passage / source note | G39: Required fix / comment | H39: Reviewer
A40: 1
A41: 2
A42: 3
A43: 4
A44: 5
A45: 6
A46: 7
A47: 8
A48: 9
A49: 10
A50: 11
A51: 12
...

Sheet Q10
A1: Q10 — Expert Review | I1: Back to status
A3: Question metadata
A4: Question ID | B4: 10
A5: Topic | B5: Food delivery — minority shareholdings
A6: Scope | B6: EU + UK
A7: Original reviewer | B7: Carolina
A8: Original status | B8: Approved
A10: Question | B10: Material influence and minority shareholdings — on what basis did the CMA take jurisdiction over a c.16% stake, and how else have authorities treated minority shareholdings in merger control?
A14: Generated answer
A15: Paste the generated answer below.
A19: Run ID | C19: Run date | E19: Model / prompt version | G19: Corpus snapshot
A20: Retrieval set review
A21: Rank | B21: Retrieved source | C21: Source type | D21: Jurisdiction | E21: URL / Document ID | F21: Returned by engine? | G21: Required source? | H21: Trap? | I21: Expert verdict | J21: Notes
A22: 1
A23: 2
A24: 3
A25: 4
A26: 5
A27: 6
A28: 7
A29: 8
A30: 9
A31: 10
A32: 11
A33: 12
... A36: 15
A38: Claim-by-claim review
A39: Claim ID | B39: Claim from answer | C39: Citation used | D39: Expert verdict | E39: Issue type | F39: Cited passage / source note | G39: Required fix / comment | H39: Reviewer
A40: 1
A41: 2
A42: 3
A43: 4
A44: 5
A45: 6
A46: 7
A47: 8
A48: 9
A49: 10
A50: 11
A51: 12
...

Sheet Q11
A1: Q11 — Expert Review | I1: Back to status
A3: Question metadata
A4: Question ID | B4: 11
A5: Topic | B5: Food delivery — evolution of practice
A6: Scope | B6: EU + UK + ES
A7: Original reviewer | B7: Carolina
A8: Original status | B8: Approved
A10: Question | B10: The evolution of European food-delivery merger control, 2017–2025 — how has practice evolved from the first national marketplace consolidations to the recent Commission decisions?
A14: Generated answer
A15: Paste the generated answer below.
A19: Run ID | C19: Run date | E19: Model / prompt version | G19: Corpus snapshot
A20: Retrieval set review
A21: Rank | B21: Retrieved source | C21: Source type | D21: Jurisdiction | E21: URL / Document ID | F21: Returned by engine? | G21: Required source? | H21: Trap? | I21: Expert verdict | J21: Notes
A22: 1
A23: 2
A24: 3
A25: 4
A26: 5
A27: 6
A28: 7
A29: 8
A30: 9
A31: 10
A32: 11
A33: 12
... A36: 15
A38: Claim-by-claim review
A39: Claim ID | B39: Claim from answer | C39: Citation used | D39: Expert verdict | E39: Issue type | F39: Cited passage / source note | G39: Required fix / comment | H39: Reviewer
A40: 1
A41: 2
A42: 3
A43: 4
A44: 5
A45: 6
A46: 7
A47: 8
A48: 9
A49: 10
A50: 11
A51: 12
...

Sheet Q12
A1: Q12 — Expert Review | I1: Back to status
A3: Question metadata
A4: Question ID | B4: 12
A5: Topic | B5: Dawn raids — legal professional privilege
A6: Scope | B6: France
A7: Original reviewer | B7: Carolina
A8: Original status | B8: Approved
A10: Question | B10: At what stage is attorney-client privilege breached during a dawn raid — when the inspector reads the document, or only when it is later used?
A14: Generated answer
A15: Paste the generated answer below.
A19: Run ID | C19: Run date | E19: Model / prompt version | G19: Corpus snapshot
A20: Retrieval set review
A21: Rank | B21: Retrieved source | C21: Source type | D21: Jurisdiction | E21: URL / Document ID | F21: Returned by engine? | G21: Required source? | H21: Trap? | I21: Expert verdict | J21: Notes
A22: 1
A23: 2
A24: 3
A25: 4
A26: 5
A27: 6
A28: 7
A29: 8
A30: 9
A31: 10
A32: 11
A33: 12
... A36: 15
A38: Claim-by-claim review
A39: Claim ID | B39: Claim from answer | C39: Citation used | D39: Expert verdict | E39: Issue type | F39: Cited passage / source note | G39: Required fix / comment | H39: Reviewer
A40: 1
A41: 2
A42: 3
A43: 4
A44: 5
A45: 6
A46: 7
A47: 8
A48: 9
A49: 10
A50: 11
A51: 12
...

Sheet Q13
A1: Q13 — Expert Review | I1: Back to status
A3: Question metadata
A4: Question ID | B4: 13
A5: Topic | B5: Dawn raids — personal data
A6: Scope | B6: France
A7: Original reviewer | B7: Carolina
A8: Original status | B8: Approved
A10: Question | B10: Under what conditions must the Competition Authority protect personal data during a dawn raid? Does the GDPR apply? Must documents be sealed on request?
A14: Generated answer
A15: Paste the generated answer below.
A19: Run ID | C19: Run date | E19: Model / prompt version | G19: Corpus snapshot
A20: Retrieval set review
A21: Rank | B21: Retrieved source | C21: Source type | D21: Jurisdiction | E21: URL / Document ID | F21: Returned by engine? | G21: Required source? | H21: Trap? | I21: Expert verdict | J21: Notes
A22: 1
A23: 2
A24: 3
A25: 4
A26: 5
A27: 6
A28: 7
A29: 8
A30: 9
A31: 10
A32: 11
A33: 12
... A36: 15
A38: Claim-by-claim review
A39: Claim ID | B39: Claim from answer | C39: Citation used | D39: Expert verdict | E39: Issue type | F39: Cited passage / source note | G39: Required fix / comment | H39: Reviewer
A40: 1
A41: 2
A42: 3
A43: 4
A44: 5
A45: 6
A46: 7
A47: 8
A48: 9
A49: 10
A50: 11
A51: 12
...

Sheet Q14
A1: Q14 — Expert Review | I1: Back to status
A3: Question metadata
A4: Question ID | B4: 14
A5: Topic | B5: Dawn raids — challenging a seizure
A6: Scope | B6: France
A7: Original reviewer | B7: Carolina
A8: Original status | B8: Approved
A10: Question | B10: After a dawn raid, can the President of the Court of Appeal be seized in interim proceedings to urgently resolve attorney-client privilege disputes? On what legal basis and under what conditions?
A14: Generated answer
A15: Paste the generated answer below.
A19: Run ID | C19: Run date | E19: Model / prompt version | G19: Corpus snapshot
A20: Retrieval set review
A21: Rank | B21: Retrieved source | C21: Source type | D21: Jurisdiction | E21: URL / Document ID | F21: Returned by engine? | G21: Required source? | H21: Trap? | I21: Expert verdict | J21: Notes
A22: 1
A23: 2
A24: 3
A25: 4
A26: 5
A27: 6
A28: 7
A29: 8
A30: 9
A31: 10
A32: 11
A33: 12
... A36: 15
A38: Claim-by-claim review
A39: Claim ID | B39: Claim from answer | C39: Citation used | D39: Expert verdict | E39: Issue type | F39: Cited passage / source note | G39: Required fix / comment | H39: Reviewer
A40: 1
A41: 2
A42: 3
A43: 4
A44: 5
A45: 6
A46: 7
A47: 8
A48: 9
A49: 10
A50: 11
A51: 12
...

Sheet Q15
A1: Q15 — Expert Review | I1: Back to status
A3: Question metadata
A4: Question ID | B4: 15
A5: Topic | B5: Dawn raids — legal professional privilege
A6: Scope | B6: EU
A7: Original reviewer | B7: Carolina
A8: Original status | B8: Approved
A10: Question | B10: At what stage is attorney-client privilege breached during a European Commission inspection under Article 20 of Regulation 1/2003 — when the inspector reads the document, or only when the Commission later uses it?
A14: Generated answer
A15: Paste the generated answer below.
A19: Run ID | C19: Run date | E19: Model / prompt version | G19: Corpus snapshot
A20: Retrieval set review
A21: Rank | B21: Retrieved source | C21: Source type | D21: Jurisdiction | E21: URL / Document ID | F21: Returned by engine? | G21: Required source? | H21: Trap? | I21: Expert verdict | J21: Notes
A22: 1
A23: 2
A24: 3
A25: 4
A26: 5
A27: 6
A28: 7
A29: 8
A30: 9
A31: 10
A32: 11
A33: 12
... A36: 15
A38: Claim-by-claim review
A39: Claim ID | B39: Claim from answer | C39: Citation used | D39: Expert verdict | E39: Issue type | F39: Cited passage / source note | G39: Required fix / comment | H39: Reviewer
A40: 1
A41: 2
A42: 3
A43: 4
A44: 5
A45: 6
A46: 7
A47: 8
A48: 9
A49: 10
A50: 11
A51: 12
...

Sheet Q16
A1: Q16 — Expert Review | I1: Back to status
A3: Question metadata
A4: Question ID | B4: 16
A5: Topic | B5: Dawn raids — personal data
A6: Scope | B6: EU
A7: Original reviewer | B7: Carolina
A8: Original status | B8: Approved
A10: Question | B10: Under what conditions must the European Commission protect personal data during an inspection? Does the GDPR apply? Must documents be sealed on request?
A14: Generated answer
A15: Paste the generated answer below.
A19: Run ID | C19: Run date | E19: Model / prompt version | G19: Corpus snapshot
A20: Retrieval set review
A21: Rank | B21: Retrieved source | C21: Source type | D21: Jurisdiction | E21: URL / Document ID | F21: Returned by engine? | G21: Required source? | H21: Trap? | I21: Expert verdict | J21: Notes
A22: 1
A23: 2
A24: 3
A25: 4
A26: 5
A27: 6
A28: 7
A29: 8
A30: 9
A31: 10
A32: 11
A33: 12
... A36: 15
A38: Claim-by-claim review
A39: Claim ID | B39: Claim from answer | C39: Citation used | D39: Expert verdict | E39: Issue type | F39: Cited passage / source note | G39: Required fix / comment | H39: Reviewer
A40: 1
A41: 2
A42: 3
A43: 4
A44: 5
A45: 6
A46: 7
A47: 8
A48: 9
A49: 10
A50: 11
A51: 12
...

Sheet Q17
A1: Q17 — Expert Review | I1: Back to status
A3: Question metadata
A4: Question ID | B4: 17
A5: Topic | B5: Dawn raids — challenging a seizure
A6: Scope | B6: EU
A7: Original reviewer | B7: Carolina
A8: Original status | B8: Approved
A10: Question | B10: What procedural avenues exist to challenge seizure of privileged documents after a European Commission inspection?
A14: Generated answer
A15: Paste the generated answer below.
A19: Run ID | C19: Run date | E19: Model / prompt version | G19: Corpus snapshot
A20: Retrieval set review
A21: Rank | B21: Retrieved source | C21: Source type | D21: Jurisdiction | E21: URL / Document ID | F21: Returned by engine? | G21: Required source? | H21: Trap? | I21: Expert verdict | J21: Notes
A22: 1
A23: 2
A24: 3
A25: 4
A26: 5
A27: 6
A28: 7
A29: 8
A30: 9
A31: 10
A32: 11
A33: 12
... A36: 15
A38: Claim-by-claim review
A39: Claim ID | B39: Claim from answer | C39: Citation used | D39: Expert verdict | E39: Issue type | F39: Cited passage / source note | G39: Required fix / comment | H39: Reviewer
A40: 1
A41: 2
A42: 3
A43: 4
A44: 5
A45: 6
A46: 7
A47: 8
A48: 9
A49: 10
A50: 11
A51: 12
...

Sheet Q18
A1: Q18 — Expert Review | I1: Back to status
A3: Question metadata
A4: Question ID | B4: 18
A5: Topic | B5: Dawn raids — legal professional privilege
A6: Scope | B6: US
A7: Original reviewer | B7: Arthur
A8: Original status | B8: Approved
A10: Question | B10: At what stage is attorney-client privilege breached when US antitrust authorities gather documents — when the investigator reads the document, or only when it is later used?
A14: Generated answer
A15: Paste the generated answer below.
A19: Run ID | C19: Run date | E19: Model / prompt version | G19: Corpus snapshot
A20: Retrieval set review
A21: Rank | B21: Retrieved source | C21: Source type | D21: Jurisdiction | E21: URL / Document ID | F21: Returned by engine? | G21: Required source? | H21: Trap? | I21: Expert verdict | J21: Notes
A22: 1
A23: 2
A24: 3
A25: 4
A26: 5
A27: 6
A28: 7
A29: 8
A30: 9
A31: 10
A32: 11
A33: 12
... A36: 15
A38: Claim-by-claim review
A39: Claim ID | B39: Claim from answer | C39: Citation used | D39: Expert verdict | E39: Issue type | F39: Cited passage / source note | G39: Required fix / comment | H39: Reviewer
A40: 1
A41: 2
A42: 3
A43: 4
A44: 5
A45: 6
A46: 7
A47: 8
A48: 9
A49: 10
A50: 11
A51: 12
...

Sheet Q22
A1: Q22 — Expert Review | I1: Back to status
A3: Question metadata
A4: Question ID | B4: 22
A5: Topic | B5: Food delivery — data access
A6: Scope | B6: EU + UK
